Workbook
Name BasegameCycle: #REF!
Name JackpotHitFrequency: #REF!
Name JackpotTurnOver: #REF!
Name RTP: #REF!

Sheet rule
A2: 1.base 中M图标 wild/scatter/bonus 都有概率分裂为两个，M级图标分裂规则 根据M图标类型 按照列 去取具体的概率 base_split_symobl_x_weight
A3: 2.base 里的 wild图标和M级图标同样的规则去判断 具体概率取base_split_symobl_92_weight,
A4: 3.scatter 没有触发free时分裂的概率为90_spilt_not_triggre_free_weight，触发了free时去取需要分裂为总共几个scatter 具体权重为90_spilt_weight，具体哪一个scatter分裂 等概率随机，比如需要分裂为4个 则有1个scatter需要变为分裂图标 具体时哪一个则是 234列 等概率随机取一个
A5: 4.free里 M/wild/bonus 必定为分裂图标
A6: 5.bonus图标在base里按照94_split_weight_in_base 去变为分裂图标，变为分裂图标后 先判断第一部分的值94_spilt_value_part_1_weight_in_base_free，然后再取第二部分的值94_spilt_value_part_2_weight_in_base_free，如果bonus没变成分裂图标 则具体的值取94_spilt_value_part_1_weight_in_base_free
A7: 6.1~5个bonus 有概率触发respin6个及以上bonus直接触发respin，具体概率取94_hit_respin_random_rate，1~5个触发respin时会在棋盘非bonus位置扔上bonus图标（扔的位置等概率随机） 补齐到6个，扔的bonus 具体的值从94_spilt_value_part_1_weight_in_base_free里取
A8: 7.respin里自然落定只会出非分裂的bonus图标 具体的值取94_value_in_respin_weight，1~13 对应prize里的id 14~19对应为乘倍图标 x10/x8/x7/x5/x3/x2
A9: 8.respin里落定 bonus时有概率变为特殊的split图标 具体概率为94_change_to_95_hit_rate，根据当前棋盘上有几个普通bonus图标来取，大于5个时取6的概率。Split生效后会将棋盘上普通bonus变为分裂图标 ，分裂个数为95_split_nums_weight，分裂的位置等概率随机，当要分裂个数 大于 普通bonus总数时 ，分裂个数取普通bonus总数
A10: 9.split生效完成后 会变为分裂图标 具体的值取split_value_weight
A11: 10.split图标分裂后 按照分裂前的值 分为5类，50为第1类，100/150/200/250为第2类，500/750/2500/5000为第3类，mini/minor/major为第4类，x2/x3/x5/x7/x8/x10为第5类，每一类的另一半对应的命中概率为split_bonus_grop_hit_rate，另一半的取值为split_bonus_grop_1_hit_value_weight
A12: 11.respin里按照spin剩余次数 每一个格子有一个概率出bonus，具体为respin_bonus_hit_rate_spin_left_3 索引为当前局已经有的bonus位置，随着本次新增bonus的个数依次变化
A17: 需要跑的数据 | B17: base/free 里触发的respin 平均赢倍
B18: 方便对rtp 统计一下summary里3~11行的参数

Sheet #<pay_table>
A1: symbol ID | B1: 2K | C1: 3K | D1: 4K | E1: 5K | F1: 6K | G1: 7K | H1: 8K | I1: 9K | J1: 10K
A2: id:int<s> | B2: 2:int<s> | C2: 3:int<s> | D2: 4:int<s> | E2: 5:int<s> | F2: 6:int<s> | G2: 7:int<s> | H2: 8:int<s> | I2: 9:int<s> | J2: 10:int<s>
A3: =VLOOKUP('Pay Table'!B6,'Pay Table'!$M$3:$N$18,2,FALSE) -> 92 | B3: ='Pay Table'!C6 -> 0 | C3: ='Pay Table'!D6 -> 0 | D3: ='Pay Table'!E6 -> 0 | E3: ='Pay Table'!F6 -> 0 | F3: ='Pay Table'!G6 -> 0 | G3: ='Pay Table'!H6 -> 0 | H3: ='Pay Table'!I6 -> 0 | I3: ='Pay Table'!J6 -> 0 | J3: ='Pay Table'!K6 -> 0
A4: =VLOOKUP('Pay Table'!B7,'Pay Table'!$M$3:$N$18,2,FALSE) -> 0 | B4: 1 | C4: ='Pay Table'!D7 -> 5 | D4: ='Pay Table'!E7 -> 15 | E4: ='Pay Table'!F7 -> 50 | F4: ='Pay Table'!G7 -> 100 | G4: ='Pay Table'!H7 -> 200 | H4: ='Pay Table'!I7 -> 500 | I4: ='Pay Table'!J7 -> 750 | J4: ='Pay Table'!K7 -> 1000
A5: =VLOOKUP('Pay Table'!B8,'Pay Table'!$M$3:$N$18,2,FALSE) -> 1 | B5: 1 | C5: ='Pay Table'!D8 -> 5 | D5: ='Pay Table'!E8 -> 15 | E5: ='Pay Table'!F8 -> 50 | F5: ='Pay Table'!G8 -> 100 | G5: ='Pay Table'!H8 -> 200 | H5: ='Pay Table'!I8 -> 500 | I5: ='Pay Table'!J8 -> 750 | J5: ='Pay Table'!K8 -> 1000
A6: =VLOOKUP('Pay Table'!B9,'Pay Table'!$M$3:$N$18,2,FALSE) -> 2 | B6: 1 | C6: ='Pay Table'!D9 -> 5 | D6: ='Pay Table'!E9 -> 10 | E6: ='Pay Table'!F9 -> 25 | F6: ='Pay Table'!G9 -> 50 | G6: ='Pay Table'!H9 -> 100 | H6: ='Pay Table'!I9 -> 200 | I6: ='Pay Table'!J9 -> 300 | J6: ='Pay Table'!K9 -> 500
A7: =VLOOKUP('Pay Table'!B10,'Pay Table'!$M$3:$N$18,2,FALSE) -> 3 | B7: 1 | C7: ='Pay Table'!D10 -> 5 | D7: ='Pay Table'!E10 -> 10 | E7: ='Pay Table'!F10 -> 25 | F7: ='Pay Table'!G10 -> 50 | G7: ='Pay Table'!H10 -> 100 | H7: ='Pay Table'!I10 -> 200 | I7: ='Pay Table'!J10 -> 300 | J7: ='Pay Table'!K10 -> 500
A8: =VLOOKUP('Pay Table'!B11,'Pay Table'!$M$3:$N$18,2,FALSE) -> 4 | B8: 1 | C8: ='Pay Table'!D11 -> 5 | D8: ='Pay Table'!E11 -> 10 | E8: ='Pay Table'!F11 -> 25 | F8: ='Pay Table'!G11 -> 50 | G8: ='Pay Table'!H11 -> 100 | H8: ='Pay Table'!I11 -> 200 | I8: ='Pay Table'!J11 -> 300 | J8: ='Pay Table'!K11 -> 500
A9: =VLOOKUP('Pay Table'!B12,'Pay Table'!$M$3:$N$18,2,FALSE) -> 5 | B9: 1 | C9: ='Pay Table'!D12 -> 2 | D9: ='Pay Table'!E12 -> 5 | E9: ='Pay Table'!F12 -> 20 | F9: ='Pay Table'!G12 -> 30 | G9: ='Pay Table'!H12 -> 50 | H9: ='Pay Table'!I12 -> 75 | I9: ='Pay Table'!J12 -> 100 | J9: ='Pay Table'!K12 -> 0
A10: =VLOOKUP('Pay Table'!B13,'Pay Table'!$M$3:$N$18,2,FALSE) -> 6 | B10: 1 | C10: ='Pay Table'!D13 -> 2 | D10: ='Pay Table'!E13 -> 5 | E10: ='Pay Table'!F13 -> 20 | F10: ='Pay Table'!G13 -> 30 | G10: ='Pay Table'!H13 -> 50 | H10: ='Pay Table'!I13 -> 75 | I10: ='Pay Table'!J13 -> 100 | J10: ='Pay Table'!K13 -> 0
A11: =VLOOKUP('Pay Table'!B14,'Pay Table'!$M$3:$N$18,2,FALSE) -> 7 | B11: 1 | C11: ='Pay Table'!D14 -> 2 | D11: ='Pay Table'!E14 -> 5 | E11: ='Pay Table'!F14 -> 20 | F11: ='Pay Table'!G14 -> 30 | G11: ='Pay Table'!H14 -> 50 | H11: ='Pay Table'!I14 -> 75 | I11: ='Pay Table'!J14 -> 100 | J11: ='Pay Table'!K14 -> 0
A12: =VLOOKUP('Pay Table'!B15,'Pay Table'!$M$3:$N$18,2,FALSE) -> 8 | B12: 1 | C12: ='Pay Table'!D15 -> 2 | D12: ='Pay Table'!E15 -> 5 | E12: ='Pay Table'!F15 -> 20 | F12: ='Pay Table'!G15 -> 30 | G12: ='Pay Table'!H15 -> 50 | H12: ='Pay Table'!I15 -> 75 | I12: ='Pay Table'!J15 -> 100 | J12: ='Pay Table'!K15 -> 0
A13: =VLOOKUP('Pay Table'!B16,'Pay Table'!$M$3:$N$18,2,FALSE) -> 90 | B13: ='Pay Table'!C16 -> 0 | C13: ='Pay Table'!D16 -> 100 | D13: ='Pay Table'!E16 -> 200 | E13: ='Pay Table'!F16 -> 300 | F13: ='Pay Table'!G16 -> 500 | G13: ='Pay Table'!H16 -> 0 | H13: ='Pay Table'!I16 -> 0 | I13: ='Pay Table'!J16 -> 0 | J13: ='Pay Table'!K16 -> 0

Sheet #<prize>
A1: id:int<s> | B1: prize:int<s> | D1: type:int<s> | E1: jackpot_id:int<s>
A2: 1 | B2: =C2*100 -> 50000 | C2: 500 | D2: 1 | E2: 111204 | F2: GRAND | G2: =A2 -> 1 | I2: =C2*1.1 -> 550
A3: 2 | B3: =C3*100 -> 10000 | C3: 100 | D3: 1 | E3: 111203 | F3: MAJOR | G3: =A3 -> 2 | I3: =C3*1.1 -> 110
A4: 3 | B4: =C4*100 -> 2000 | C4: 20 | D4: 1 | E4: 111202 | F4: MINOR | G4: =A4 -> 3 | I4: =C4*1.1 -> 22
A5: 4 | B5: =C5*100 -> 1000 | C5: 10 | D5: 1 | E5: 111201 | F5: MINI | G5: =A5 -> 4 | I5: =C5*1.1 -> 11
A6: 5 | B6: =C6*100 -> 5000 | C6: 50 | D6: 0 | E6: 0 | G6: =A6 -> 5
A7: 6 | B7: =C7*100 -> 2500 | C7: 25 | D7: 0 | E7: 0 | G7: =A7 -> 6
A8: 7 | B8: =C8*100 -> 750 | C8: 7.5 | D8: 0 | E8: 0 | G8: =A8 -> 7
A9: 8 | B9: =C9*100 -> 500 | C9: 5 | D9: 0 | E9: 0 | G9: =A9 -> 8
A10: 9 | B10: =C10*100 -> 250 | C10: 2.5 | D10: 0 | E10: 0 | G10: =A10 -> 9
A11: 10 | B11: =C11*100 -> 200 | C11: 2 | D11: 0 | E11: 0 | G11: =A11 -> 10
A12: 11 | B12: =C12*100 -> 150 | C12: 1.5 | D12: 0 | E12: 0 | G12: =A12 -> 11
A13: 12 | B13: =C13*100 -> 100 | C13: 1 | D13: 0 | E13: 0 | G13: =A13 -> 12
A14: 13 | B14: =C14*100 -> 50 | C14: 0.5 | D14: 0 | E14: 0 | G14: =A14 -> 13

Sheet #<base_reel_strip>
B1: reelstripID
A2: id:int<s> | B2: reel_id:int<s> | C2: col:int<s> | D2: strip:array<s>
A3: 1 | B3: 1 | C3: 1 | D3: =_xlfn.TEXTJOIN(",",TRUE,'Base Game '!BB4:BB401) -> [3,100],[2,100],[5,100],[94,15],[94,25],[94,50],[5,100],[7,100],[3,100],[0,100],[0,100],[0,100],[7,100],[6,100],[4,100],[6,100],[4,100],[4,100],[0,100],[0,100],[0,100],[6,100],[3,100],[6,100],[2,100],[2,100],[3,100],[8,100],[2,100],[4,100],[4,100],[5,100],[6,100],[2,100],[7,100],[1,100],[1,100],[1,100],[5,100],[6,100],[94,50],[3,100],[94,100],[8,100],[2,100],[1,100],[1,100],[7,100],[3,100],[6,100],[7,100],[2,100],[4,100],[4,100],[0,100],[5,100],[2,100],[3,100],[5,100],[2,100],[3,100]
A4: =A3+1 -> 2 | B4: 1 | C4: =C3+1 -> 2 | D4: =_xlfn.TEXTJOIN(",",TRUE,'Base Game '!BC4:BC401) -> [1,100],[7,100],[92,100],[5,140],[90,144],[6,100],[4,100],[4,100],[2,100],[6,100],[5,100],[2,100],[2,100],[8,100],[5,100],[7,100],[4,100],[8,100],[92,100],[2,100],[4,100],[8,100],[7,100],[1,100],[1,100],[1,100],[3,100],[5,140],[90,150],[6,100],[1,100],[1,100],[1,100],[6,100],[94,15],[94,25],[94,50],[3,100],[3,100],[7,150],[90,200],[7,100],[0,100],[8,100],[94,50],[2,100],[94,100],[4,100],[4,200],[92,100],[6,100],[4,100],[0,100],[0,100],[0,100],[5,100],[2,100],[8,100]
A5: =A4+1 -> 3 | B5: 1 | C5: =C4+1 -> 3 | D5: =_xlfn.TEXTJOIN(",",TRUE,'Base Game '!BD4:BD401) -> [0,100],[0,100],[0,100],[5,140],[90,144],[8,100],[2,100],[3,100],[0,100],[0,100],[7,100],[3,100],[7,100],[8,100],[7,100],[92,100],[7,100],[0,100],[0,100],[0,100],[5,100],[1,100],[4,100],[4,100],[2,130],[90,135],[7,100],[1,100],[1,100],[1,100],[6,100],[5,100],[94,50],[7,100],[94,100],[6,100],[3,100],[92,100],[6,100],[1,100],[1,100],[1,100],[6,100],[8,100],[3,100],[4,100],[3,100],[6,180],[90,195],[8,100],[0,100],[92,100],[5,100],[94,15],[94,25],[94,50],[6,100]
A6: =A5+1 -> 4 | B6: 1 | C6: =C5+1 -> 4 | D6: =_xlfn.TEXTJOIN(",",TRUE,'Base Game '!BE4:BE401) -> [1,100],[1,100],[7,100],[8,100],[5,100],[3,100],[3,100],[5,100],[4,100],[0,100],[4,100],[2,100],[5,100],[92,100],[4,100],[8,100],[5,100],[4,100],[0,100],[0,100],[0,100],[5,100],[1,100],[1,100],[1,200],[6,190],[90,200],[5,100],[4,100],[2,100],[92,100],[3,100],[7,100],[0,100],[0,100],[0,100],[8,100],[94,50],[6,100],[94,100],[6,100],[3,100],[8,210],[7,210],[90,200],[6,100],[3,100],[6,100],[1,100],[1,100],[8,100],[94,15],[94,25],[94,50],[5,100],[3,100],[7,100],[8,100],[7,100],[92,100],[7,100],[8,100],[6,100],[1,100],[1,100],[1,100],[4,100],[8,100],[7,100],[2,100],[2,100],[7,100],[6,100],[4,100],[0,100],[0,100],[0,100],[5,100],[6,100],[1,100]
A7: =A6+1 -> 5 | B7: 1 | C7: =C6+1 -> 5 | D7: {=_xlfn.TEXTJOIN(",",TRUE,'Base Game '!BF4:BF176)} -> [3,100],[6,100],[94,15],[94,25],[94,50],[7,100],[0,100],[5,100],[6,100],[1,100],[1,100],[1,100],[6,100],[8,100],[2,100],[2,100],[3,100],[92,100],[6,100],[8,100],[94,50],[3,100],[94,100],[8,100],[7,100],[1,100],[1,100],[1,100],[2,100],[2,100],[5,100],[7,100],[6,100],[0,100],[0,100],[0,100],[4,100],[1,100],[8,100],[2,100],[6,100],[5,100],[3,100],[3,100],[8,100],[0,100],[0,100],[0,100],[92,100],[4,100],[1,100],[3,100],[4,100],[4,100],[0,100],[0,100],[0,100],[7,100],[1,100],[1,100],[1,100],[7,100],[6,100],[92,100],[6,100],[7,100],[0,100],[0,100],[0,100],[6,100],[5,100]
F620: =IF([1]Base3!B201="","",",["&VLOOKUP([1]Base3!B201,'[1]#<config>'!$D$2:$E$18,2,0)&",10]") | G620: =IF([1]Base3!C201="","",",["&VLOOKUP([1]Base3!C201,'[1]#<config>'!$D$2:$E$18,2,0)&",10]") | H620: =IF([1]Base3!D201="","",",["&VLOOKUP([1]Base3!D201,'[1]#<config>'!$D$2:$E$18,2,0)&",10]") | I620: =IF([1]Base3!E201="","",",["&VLOOKUP([1]Base3!E201,'[1]#<config>'!$D$2:$E$18,2,0)&",10]") | J620: =IF([1]Base3!F201="","",",["&VLOOKUP([1]Base3!F201,'[1]#<config>'!$D$2:$E$18,2,0)&",10]")
F621: =IF([1]Base3!B202="","",",["&VLOOKUP([1]Base3!B202,'[1]#<config>'!$D$2:$E$18,2,0)&",10]") | G621: =IF([1]Base3!C202="","",",["&VLOOKUP([1]Base3!C202,'[1]#<config>'!$D$2:$E$18,2,0)&",10]") | H621: =IF([1]Base3!D202="","",",["&VLOOKUP([1]Base3!D202,'[1]#<config>'!$D$2:$E$18,2,0)&",10]") | I621: =IF([1]Base3!E202="","",",["&VLOOKUP([1]Base3!E202,'[1]#<config>'!$D$2:$E$18,2,0)&",10]") | J621: =IF([1]Base3!F202="","",",["&VLOOKUP([1]Base3!F202,'[1]#<config>'!$D$2:$E$18,2,0)&",10]")
F622: =IF([1]Base3!B203="","",",["&VLOOKUP([1]Base3!B203,'[1]#<config>'!$D$2:$E$18,2,0)&",10]") | G622: =IF([1]Base3!C203="","",",["&VLOOKUP([1]Base3!C203,'[1]#<config>'!$D$2:$E$18,2,0)&",10]") | H622: =IF([1]Base3!D203="","",",["&VLOOKUP([1]Base3!D203,'[1]#<config>'!$D$2:$E$18,2,0)&",10]") | I622: =IF([1]Base3!E203="","",",["&VLOOKUP([1]Base3!E203,'[1]#<config>'!$D$2:$E$18,2,0)&",10]") | J622: =IF([1]Base3!F203="","",",["&VLOOKUP([1]Base3!F203,'[1]#<config>'!$D$2:$E$18,2,0)&",10]")
F623: =IF([1]Base3!B204="","",",["&VLOOKUP([1]Base3!B204,'[1]#<config>'!$D$2:$E$18,2,0)&",10]") | G623: =IF([1]Base3!C204="","",",["&VLOOKUP([1]Base3!C204,'[1]#<config>'!$D$2:$E$18,2,0)&",10]") | H623: =IF([1]Base3!D204="","",",["&VLOOKUP([1]Base3!D204,'[1]#<config>'!$D$2:$E$18,2,0)&",10]") | I623: =IF([1]Base3!E204="","",",["&VLOOKUP([1]Base3!E204,'[1]#<config>'!$D$2:$E$18,2,0)&",10]") | J623: =IF([1]Base3!F204="","",",["&VLOOKUP([1]Base3!F204,'[1]#<config>'!$D$2:$E$18,2,0)&",10]")

Sheet #<free_reel_strip>
B1: reelstripID
A2: id:int<s> | B2: reel_id:int<s> | C2: col:int<s> | D2: strip:array<s>
A3: 1 | B3: 1 | C3: 1 | D3: =_xlfn.TEXTJOIN(",",TRUE,'Free Game'!BB3:BB400) -> [1,100],[3,100],[7,100],[94,5],[94,10],[94,25],[6,100],[7,100],[2,100],[4,100],[3,100],[8,100],[5,100],[3,100],[4,100],[6,100],[0,100],[0,100],[2,100],[8,100],[2,100],[3,100],[2,100],[7,100],[6,100],[1,100],[1,100],[4,100],[4,100],[8,100],[1,100],[6,100],[4,100],[2,100],[5,100],[1,100],[1,100],[1,100],[5,100],[4,100],[2,25],[6,25],[94,25],[8,100],[2,100],[3,100],[4,100],[7,100],[8,100],[3,100],[0,100],[0,100],[0,100],[8,100],[7,100],[4,100],[2,100],[3,100],[5,100],[6,100],[3,100]
A4: =A3+1 -> 2 | B4: 1 | C4: =C3+1 -> 2 | D4: =_xlfn.TEXTJOIN(",",TRUE,'Free Game'!BC3:BC400) -> [3,100],[0,100],[0,100],[0,100],[4,100],[6,100],[4,100],[92,100],[92,100],[2,100],[5,100],[8,100],[1,100],[1,100],[1,100],[7,100],[8,100],[6,100],[92,100],[7,100],[3,100],[4,100],[4,100],[0,100],[0,100],[0,100],[6,100],[5,100],[7,100],[2,100],[1,100],[3,100],[3,100],[6,100],[94,5],[94,10],[94,25],[8,100],[6,100],[2,100],[0,100],[4,100],[8,100],[1,100],[2,25],[2,25],[94,25],[8,100],[92,100],[92,100],[92,100],[7,100],[5,100],[1,100],[1,100],[1,100],[6,100],[3,100]
A5: =A4+1 -> 3 | B5: 1 | C5: =C4+1 -> 3 | D5: =_xlfn.TEXTJOIN(",",TRUE,'Free Game'!BD3:BD400) -> [4,100],[92,100],[92,100],[92,100],[2,100],[8,100],[3,100],[3,100],[1,100],[1,100],[1,100],[6,100],[3,100],[5,100],[2,100],[0,100],[0,100],[4,100],[8,100],[5,100],[92,100],[0,100],[0,100],[0,100],[2,100],[7,100],[6,100],[0,100],[0,100],[0,100],[6,100],[5,100],[2,10],[7,25],[94,25],[6,100],[92,100],[8,100],[6,100],[0,100],[0,100],[2,100],[2,100],[8,100],[4,100],[6,100],[7,100],[1,100],[1,100],[1,100],[2,100],[4,100],[4,100],[94,5],[94,10],[94,25],[7,100]
A6: =A5+1 -> 4 | B6: 1 | C6: =C5+1 -> 4 | D6: =_xlfn.TEXTJOIN(",",TRUE,'Free Game'!BE3:BE400) -> [6,100],[0,100],[0,100],[0,100],[5,100],[3,100],[6,100],[92,100],[92,100],[92,100],[8,100],[2,100],[6,100],[4,100],[2,100],[0,100],[92,100],[4,100],[5,100],[7,100],[0,100],[5,100],[8,100],[2,100],[7,100],[1,100],[1,100],[92,100],[4,100],[2,100],[8,100],[3,100],[1,100],[1,100],[1,100],[3,100],[3,100],[2,25],[6,25],[94,25],[6,100],[2,100],[2,100],[1,100],[5,100],[6,100],[0,100],[0,100],[0,100],[2,100],[8,100],[94,5],[94,10],[94,25],[6,100],[8,100],[2,100],[92,100],[4,100],[5,100],[2,100],[92,100],[3,100],[8,100],[4,100],[4,100],[0,100],[0,100],[0,100],[6,100],[2,100],[7,100],[6,100],[92,100],[6,100],[7,100],[8,100],[1,100],[1,100],[1,100]
A7: =A6+1 -> 5 | B7: 1 | C7: =C6+1 -> 5 | D7: =_xlfn.TEXTJOIN(",",TRUE,'Free Game'!BF3:BF253) -> [1,100],[6,100],[94,5],[94,10],[94,25],[4,100],[7,100],[8,100],[5,100],[4,100],[1,100],[1,100],[6,100],[8,100],[92,100],[0,100],[0,100],[0,100],[6,100],[5,100],[2,25],[2,25],[94,25],[8,100],[7,100],[6,100],[92,100],[92,100],[92,100],[3,100],[5,100],[4,100],[0,100],[0,100],[0,100],[6,100],[4,100],[1,100],[1,100],[1,100],[5,100],[6,100],[2,100],[8,100],[92,100],[5,100],[7,100],[3,100],[3,100],[1,100],[1,100],[1,100],[6,100],[2,100],[4,100],[0,100],[0,100],[0,100],[7,100],[4,100],[4,100],[3,100],[6,100],[92,100],[2,100],[7,100],[5,100],[4,100],[3,100],[1,100],[1,100]
F620: =IF([1]Base3!B201="","",",["&VLOOKUP([1]Base3!B201,'[1]#<config>'!$D$2:$E$18,2,0)&",10]") | G620: =IF([1]Base3!C201="","",",["&VLOOKUP([1]Base3!C201,'[1]#<config>'!$D$2:$E$18,2,0)&",10]") | H620: =IF([1]Base3!D201="","",",["&VLOOKUP([1]Base3!D201,'[1]#<config>'!$D$2:$E$18,2,0)&",10]") | I620: =IF([1]Base3!E201="","",",["&VLOOKUP([1]Base3!E201,'[1]#<config>'!$D$2:$E$18,2,0)&",10]") | J620: =IF([1]Base3!F201="","",",["&VLOOKUP([1]Base3!F201,'[1]#<config>'!$D$2:$E$18,2,0)&",10]")
F621: =IF([1]Base3!B202="","",",["&VLOOKUP([1]Base3!B202,'[1]#<config>'!$D$2:$E$18,2,0)&",10]") | G621: =IF([1]Base3!C202="","",",["&VLOOKUP([1]Base3!C202,'[1]#<config>'!$D$2:$E$18,2,0)&",10]") | H621: =IF([1]Base3!D202="","",",["&VLOOKUP([1]Base3!D202,'[1]#<config>'!$D$2:$E$18,2,0)&",10]") | I621: =IF([1]Base3!E202="","",",["&VLOOKUP([1]Base3!E202,'[1]#<config>'!$D$2:$E$18,2,0)&",10]") | J621: =IF([1]Base3!F202="","",",["&VLOOKUP([1]Base3!F202,'[1]#<config>'!$D$2:$E$18,2,0)&",10]")
F622: =IF([1]Base3!B203="","",",["&VLOOKUP([1]Base3!B203,'[1]#<config>'!$D$2:$E$18,2,0)&",10]") | G622: =IF([1]Base3!C203="","",",["&VLOOKUP([1]Base3!C203,'[1]#<config>'!$D$2:$E$18,2,0)&",10]") | H622: =IF([1]Base3!D203="","",",["&VLOOKUP([1]Base3!D203,'[1]#<config>'!$D$2:$E$18,2,0)&",10]") | I622: =IF([1]Base3!E203="","",",["&VLOOKUP([1]Base3!E203,'[1]#<config>'!$D$2:$E$18,2,0)&",10]") | J622: =IF([1]Base3!F203="","",",["&VLOOKUP([1]Base3!F203,'[1]#<config>'!$D$2:$E$18,2,0)&",10]")
F623: =IF([1]Base3!B204="","",",["&VLOOKUP([1]Base3!B204,'[1]#<config>'!$D$2:$E$18,2,0)&",10]") | G623: =IF([1]Base3!C204="","",",["&VLOOKUP([1]Base3!C204,'[1]#<config>'!$D$2:$E$18,2,0)&",10]") | H623: =IF([1]Base3!D204="","",",["&VLOOKUP([1]Base3!D204,'[1]#<config>'!$D$2:$E$18,2,0)&",10]") | I623: =IF([1]Base3!E204="","",",["&VLOOKUP([1]Base3!E204,'[1]#<config>'!$D$2:$E$18,2,0)&",10]") | J623: =IF([1]Base3!F204="","",",["&VLOOKUP([1]Base3!F204,'[1]#<config>'!$D$2:$E$18,2,0)&",10]")

Sheet #<config>
A1: name:string<s> | B1: string_value:string<s> | C1: int_value:int<s> | D1: array_value:array<s>
A2: bet | C2: ='Pay Table'!B2*'Pay Table'!G2 -> 100 | E2: ='Pay Table'!B6 -> WILD | F2: =VLOOKUP(E2,'Pay Table'!$M$3:$N$18,2,FALSE) -> 92
A3: row | C3: 3 | E3: ='Pay Table'!B7 -> M1 | F3: =VLOOKUP(E3,'Pay Table'!$M$3:$N$18,2,FALSE) -> 0
A4: col | C4: 5 | E4: ='Pay Table'!B8 -> M2 | F4: =VLOOKUP(E4,'Pay Table'!$M$3:$N$18,2,FALSE) -> 1
E5: ='Pay Table'!B9 -> M3 | F5: =VLOOKUP(E5,'Pay Table'!$M$3:$N$18,2,FALSE) -> 2
A6: symbols | D6: =_xlfn.TEXTJOIN(",",TRUE,F3:F11) -> 0,1,2,3,4,5,6,7,8 | E6: ='Pay Table'!B10 -> M4 | F6: =VLOOKUP(E6,'Pay Table'!$M$3:$N$18,2,FALSE) -> 3
A7: wild | D7: =F2 -> 92 | E7: ='Pay Table'!B11 -> M5 | F7: =VLOOKUP(E7,'Pay Table'!$M$3:$N$18,2,FALSE) -> 4
A8: bonus | D8: =F13 -> 94 | E8: ='Pay Table'!B12 -> A | F8: =VLOOKUP(E8,'Pay Table'!$M$3:$N$18,2,FALSE) -> 5
A9: bonus2 | D9: =F14 -> 95 | E9: ='Pay Table'!B13 -> K | F9: =VLOOKUP(E9,'Pay Table'!$M$3:$N$18,2,FALSE) -> 6
A10: scatter | D10: =F12 -> 90 | E10: ='Pay Table'!B14 -> Q | F10: =VLOOKUP(E10,'Pay Table'!$M$3:$N$18,2,FALSE) -> 7
A11: jackpots | D11: =_xlfn.TEXTJOIN(",",TRUE,'#<prize>'!E2:E5) -> 111204,111203,111202,111201 | E11: ='Pay Table'!B15 -> J | F11: =VLOOKUP(E11,'Pay Table'!$M$3:$N$18,2,FALSE) -> 8
E12: ='Pay Table'!B16 -> SCATTER | F12: =VLOOKUP(E12,'Pay Table'!$M$3:$N$18,2,FALSE) -> 90
A13: line | B13: 3X5_50 | E13: ='Pay Table'!B17 -> LINK | F13: =VLOOKUP(E13,'Pay Table'!$M$3:$N$18,2,FALSE) -> 94
A14: rule | C14: 0 | E14: LINK_SPILT | F14: 95
A16: base_strip_weights | D16: ="[1,"&1*10000&"]" -> [1,10000]
A18: free_strip_weights | D18: ="[1,"&1*10000&"]" -> [1,10000]
A20: trigger_free_min_scatter_count | C20: ='Pay Table'!U3 -> 3
A21: respin_times | C21: 3
A23: base_split_symbol_92_weight | D23: {=_xlfn.TEXTJOIN(",",TRUE,"["&'Base Game '!AC93:AG93&",["&'Base Game '!AC94:AG94*10000&","&10000&"]]")} -> [1,[500,10000]],[2,[800,10000]],[3,[3500,10000]],[4,[5000,10000]],[5,[6500,10000]]
A24: base_split_symbol_0_weight | D24: {=_xlfn.TEXTJOIN(",",TRUE,"["&'Base Game '!AC93:AG93&",["&'Base Game '!AC95:AG95*10000&","&10000&"]]")} -> [1,[2000,10000]],[2,[6000,10000]],[3,[8000,10000]],[4,[8500,10000]],[5,[9000,10000]]
A25: base_split_symbol_1_weight | D25: {=_xlfn.TEXTJOIN(",",TRUE,"["&'Base Game '!AC93:AG93&",["&'Base Game '!AC96:AG96*10000&","&10000&"]]")} -> [1,[2000,10000]],[2,[6000,10000]],[3,[7000,10000]],[4,[8500,10000]],[5,[9000,10000]]
A26: base_split_symbol_2_weight | D26: {=_xlfn.TEXTJOIN(",",TRUE,"["&'Base Game '!AC93:AG93&",["&'Base Game '!AC97:AG97*10000&","&10000&"]]")} -> [1,[1000,10000]],[2,[2200,10000]],[3,[4500,10000]],[4,[7500,10000]],[5,[8500,10000]]
A27: base_split_symbol_3_weight | D27: {=_xlfn.TEXTJOIN(",",TRUE,"["&'Base Game '!AC93:AG93&",["&'Base Game '!AC98:AG98*10000&","&10000&"]]")} -> [1,[1000,10000]],[2,[2200,10000]],[3,[4500,10000]],[4,[7500,10000]],[5,[8500,10000]]
A28: base_split_symbol_4_weight | D28: {=_xlfn.TEXTJOIN(",",TRUE,"["&'Base Game '!AC93:AG93&",["&'Base Game '!AC99:AG99*10000&","&10000&"]]")} -> [1,[1000,10000]],[2,[2200,10000]],[3,[4500,10000]],[4,[7500,10000]],[5,[8500,10000]]
A31: 90_spilt_weight | D31: {=_xlfn.TEXTJOIN(",",TRUE,"["&'Base Game '!O130:R130&","&'Base Game '!O131:R131&"]")} -> [3,30],[4,100],[5,50],[6,12]
A32: 90_spilt_not_trigger_free_weight | D32: {=_xlfn.TEXTJOIN(",",TRUE,'Base Game '!U130*100&","&100)} -> 50,100
A33: 94_hit_respin_random_rate | D33: {=_xlfn.TEXTJOIN(",",TRUE,"["&'Base Game '!O144:T144&",["&'Base Game '!O148:T148*10000&","&10000&"]]")} -> [0,[0,10000]],[1,[5,10000]],[2,[55,10000]],[3,[190,10000]],[4,[300,10000]],[5,[700,10000]]
A34: 94_split_weight_in_base | D34: {=_xlfn.TEXTJOIN(",",TRUE,Respin!P74*10000&","&10000)} -> 2000,10000
A35: 94_spilt_value_part_1_weight_in_base_free | D35: {=_xlfn.TEXTJOIN(",",TRUE,"["&Respin!A38:A50&","&Respin!C22:C34&"]")} -> [1,0],[2,2],[3,46],[4,185],[5,7],[6,20],[7,100],[8,250],[9,800],[10,1200],[11,1650],[12,1900],[13,1880]
A36: 94_spilt_value_part_2_weight_in_base_free | D36: {=_xlfn.TEXTJOIN(",",TRUE,"["&Respin!A38:A56&","&Respin!C38:C56&"]")} -> [1,0],[2,1],[3,8],[4,25],[5,2],[6,3],[7,80],[8,100],[9,250],[10,300],[11,100],[12,0],[13,0],[1000,2],[800,5],[700,15],[500,150],[300,350],[200,700]
A38: 94_value_in_respin_weight | D38: {=_xlfn.TEXTJOIN(",",TRUE,"["&Respin!A38:A56&","&Respin!C61:C79&"]")} -> [1,0],[2,1],[3,20],[4,55],[5,2],[6,8],[7,40],[8,135],[9,250],[10,330],[11,350],[12,750],[13,900],[1000,0],[800,0],[700,0],[500,0],[300,0],[200,0]
A39: 94_change_to_95_hit_rate | D39: {=_xlfn.TEXTJOIN(",",TRUE,"["&Respin!I93:I107&",["&Respin!J93:J107*10000&","&10000&"]]")} -> [14,[4000,10000]],[13,[5500,10000]],[12,[5500,10000]],[11,[5500,10000]],[10,[5000,10000]],[9,[4500,10000]],[8,[4000,10000]],[7,[4000,10000]],[6,[4000,10000]],[5,[3000,10000]],[4,[2000,10000]],[3,[1500,10000]],[2,[800,10000]],[1,[500,10000]],[0,[0,10000]]
A40: 95_split_nums_weight | D40: {=_xlfn.TEXTJOIN(",",TRUE,"["&Respin!L84:L88&","&Respin!M84:M88&"]")} -> [5,3],[4,10],[3,15],[2,4],[1,0]
A41: split_value_weight | D41: {=_xlfn.TEXTJOIN(",",TRUE,"["&Respin!X93:X110&","&Respin!Z93:Z110&"]")} -> [2,0],[3,0],[4,0],[5,0],[6,0],[7,0],[8,0],[9,0],[10,0],[11,0],[12,0],[13,0],[1000,15],[800,50],[700,150],[500,300],[300,350],[200,300]
A43: split_bonus_group_hit_rate | D43: {=_xlfn.TEXTJOIN(",",TRUE,"["&Respin!P78:P82&",["&Respin!Q78:Q82*100&","&100&"]]")} -> [1,[13.5,100]],[2,[14,100]],[3,[11,100]],[4,[10,100]],[5,[10,100]]
A45: split_bonus_group_1_hit_value_weight | D45: {=_xlfn.TEXTJOIN(",",TRUE,"["&Respin!A39:A56&","&Respin!M93:M110&"]")} -> [2,0],[3,0],[4,100],[5,3],[6,10],[7,50],[8,100],[9,500],[10,800],[11,1000],[12,500],[13,100],[1000,30],[800,80],[700,150],[500,250],[300,1000],[200,2000]
A46: split_bonus_group_2_hit_value_weight | D46: {=_xlfn.TEXTJOIN(",",TRUE,"["&Respin!A39:A56&","&Respin!Q93:Q110&"]")} -> [2,0],[3,0],[4,10],[5,1],[6,5],[7,10],[8,50],[9,80],[10,100],[11,150],[12,0],[13,0],[1000,10],[800,30],[700,45],[500,80],[300,150],[200,250]
A47: split_bonus_group_3_hit_value_weight | D47: {=_xlfn.TEXTJOIN(",",TRUE,"["&Respin!A39:A56&","&Respin!U93:U110&"]")} -> [2,1],[3,10],[4,150],[5,2],[6,10],[7,250],[8,400],[9,80],[10,30],[11,0],[12,0],[13,0],[1000,28],[800,80],[700,250],[500,350],[300,500],[200,650]
A48: split_bonus_group_4_hit_value_weight | D48: {=_xlfn.TEXTJOIN(",",TRUE,"["&Respin!A39:A56&","&Respin!M115:M132&"]")} -> [2,2],[3,35],[4,200],[5,5],[6,25],[7,100],[8,150],[9,400],[10,550],[11,650],[12,450],[13,150],[1000,38],[800,300],[700,450],[500,1300],[300,1800],[200,2000]
A49: split_bonus_group_5_hit_value_weight | D49: {=_xlfn.TEXTJOIN(",",TRUE,"["&Respin!A39:A56&","&Respin!Q115:Q132&"]")} -> [2,2],[3,35],[4,150],[5,25],[6,80],[7,450],[8,1000],[9,2500],[10,3500],[11,1500],[12,500],[13,0],[1000,0],[800,0],[700,0],[500,0],[300,0],[200,0]
...

Sheet Summary
M1: 竞品情况 | N1: 1.base 里奖线命中率 35%左右，给的倍数偏低 。赢倍基本上就是1倍以下0.5倍左右 很难看到大赢倍，分裂M图标在base没啥存在感
A2: Total RTP： | B2: =B3+B4+B5 -> 0.90168195 | N2: 2.触发respin 随机触发占比不低与直接落定6个及以上bonus触发大概比例在4:3,给的倍数不低，统计的数据是44.59倍
A3: Base Game Line RTP： | B3: ='Base Game '!O161 -> 0.31446142 | N3: 3.respin 结束平均落定10.57个bonus，其中51.35%是split图标 ，48.6%是普通的图标，split图标里 又有10.5%是无效的bonus（就是分裂后一半是倍数一半是空 这个不参与最后的赔付）
A4: Free Game RTP： | B4: ='Free Game'!O105+'Free Game'!O110 -> 0.2054437 | N4: 4.free里wild出现概率挺高，wild不堆叠都是单个单个的wild，free里M图标分裂存在感就很强 因为wild变多了 比起base 奖线命中率直线上升，M分裂图标存在感就很强 能看到 奖线大赢倍
A5: Base Respin Game RTP： | B5: =Respin!C85 -> 0.38177684 | N5: 5.free里触发respin 统计的数据 大概是 8次free 有2次free里触发了respin。Free里不中大奖线或者respin的话 整体倍数就偏低。
A6: Free Game Hit Frequency： | B6: ='Base Game '!O164 -> 158.34337
A7: Base Respin Game Frequency： | B7: ='Base Game '!O167 -> 109.31265
A8: Total Bonus Game Frequency： | B8: =1/(1/B6+1/B7) -> 64.668574 | M8: 与竞品的区别 | N8: 玩法与竞品玩法有区别,wild改为概率变为2个(原版wild与M图标产生赔付算2个 与AKQJ算1个,一个位置上wild同时与M和AKQJ产生赔付会有2种状态)，free期间bonus 必定是2个(原版是概率变2个),
A9: Avg Bonus Nums： | B9: =Respin!C83 -> 10.819853 | N9: 去掉了首列wild（原版首列有wild以及wild有赔付奖线逻辑要改动到底层，这样修改成本最低）
A10: Avg Free Nums: | B10: ='Free Game'!O107 -> 8.4583333
A11: Avg Respin Mul in Base : | B11: =Respin!C84 -> 41.733037 | M11: v1： | N11: 出版图标M3M4M5没底板 看起来盘面就比较空，没有竞品m级图标堆到一起的感觉，和策划沟通后原画改动成本较高，从数值上入手成本较小
A12: Avg Respin Mul in Free : | B12: ='Free Game'!O113 -> 42.438925 | N12: 将轮带里m1 m2图标做2连3连堆叠减弱盘面太空的感觉,free里保持一致也添加了m1m2的堆叠 强化m1 m2的存在感，也正好贴合free转场时两个忍者拼刀的感觉
N13: base里12列加了m1/m2的2连堆叠，345加了3连堆叠，free里强化了一下 第2345列也加了m1/m2的三连堆叠, 调整paytable 降低m3m4m5, 6/7/8 连赔付与m2 做区分
B14: 触发概率 | C14: 间隔 | D14: 平均赢倍 | E14: RTP
A15: Base Line Game | B15: 0.340547 | C15: =1/B15 -> 2.9364522 | D15: =E15/B15 -> 0.92340093 | E15: ='Base Game '!O161 -> 0.31446142 | M15: v2: | N15: respin 怎么进怎么出一个没中这体验很差 提升bonus 6个及以下的出球概率 降低10个11个出球的概率，平均出球数保持不变 10.6
A16: Free Games Line Games | B16: ='Base Game '!O163 -> 0.0063153893 | C16: =1/B16 -> 158.34337 | D16: ='Free Game'!O108 -> 23.503155 | E16: ='Free Game'!O105 -> 0.15543157 | N16: 出现第一个太刀速度有点太快了 刚开始spin几下就出 没有nearmiss体验 出首个太刀的概率降到45%
A17: Base Trigger Respin Games | B17: ='Base Game '!O166 -> 0.0091480723 | C17: =1/B17 -> 109.31265 | D17: =Respin!C84 -> 41.733037 | E17: =B5 -> 0.38177684
A18: Free Trigger Respin Games | B18: ='Free Game'!O111 -> 0.022061041 | C18: =1/B18 -> 45.328777 | D18: ='Free Game'!O113 -> 42.438925 | E18: ='Base Game '!O163*'Free Game'!O113*'Free Game'!O111*'Free Game'!O107 -> 0.050012124 | M18: v3： | N18: 机台重点还是respin，把free里触发respin概率提升 目前是平均17.3次free触发一次respin（一轮free下来 48%的概率能中respin），保证free内部体验 提升free间隔158，把free平均赢倍提高到37倍
A19: Total Respin Games(包含free里触发respin) | B19: ='Base Game '!O166+'Base Game '!O163*'Free Game'!O107*'Free Game'!O111 -> 0.010326522 | C19: =1/B19 -> 96.838029 | D19: =Respin!C84+'Base Game '!O163*'Free Game'!O107*'Free Game'!O111*'Free Game'!O113 -> 41.783049 | E19: =D19*B19 -> 0.43147356 | N19: free触发上 触发10/12次free概率有点高，玩起来感觉多free次数不是那么稀有了，降低一点出12/10次free的概率 平均free次数从8.9次降低到8.4次
A20: Total Free Games(包含free里触发respin) | B20: ='Base Game '!O163 -> 0.0063153893 | C20: =1/B20 -> 158.34337 | D20: =E20/B20 -> 32.530647 | E20: =E16+E18 -> 0.2054437
M21: v4： | N21: free里bonus都是2个的 另一半是乘倍的概率有点高74% free里中的respin 玩起来就感觉另一半全是乘倍了 降低到54%把乘倍换成高价值的pot值
A22: 竞品数据 | B22: 触发概率 | C22: 间隔 | D22: 平均赢倍 | E22: RTP
A23: Base Line Game | B23: =竞品数据统计!H2 -> 0.34974093 | C23: =1/B23 -> 2.8592593 | D23: =E23/B23 -> 0.94701978 | E23: =竞品数据统计!I2 -> 0.33121158 | F23: 统计数据不多竞品数据仅供参考 | M23: v5： | N23: 感觉太刀出现的价值期待有点低了 降低太刀出现的概率 35%，提高base落出来的bonus的平均价值到2.5倍以上的概率 提升到21%
A24: Respin Games | B24: =竞品数据统计!K2 -> 0.0077720207 | C24: =1/B24 -> 128.66667 | D24: =竞品数据统计!K4 -> 43.410256 | E24: =竞品数据统计!K6 -> 0.33738541
A25: Free Games | B25: =竞品数据统计!S2 -> 0.0090673575 | C25: =1/B25 -> 110.28571 | D25: =竞品数据统计!S4 -> 25.562857 | E25: =竞品数据统计!S7 -> 0.23178756 | M25: v6: | N25: 提升 respin里 另一半出乘倍的概率，降低另一半出bonus的概率 ，提升出高乘倍的概率
N26: 增加轮带里m1m2的堆叠 降低paytable里的赔付，提高base里大赢的概率将base里10倍以上的概率从0.13%提升到0.47%
N27: free 里触发respin 的概率降低 增加m1m2 以及wild堆叠 将体验往奖线上放，目前33的free 奖线占23倍
M29: v7: | N29: base/free m1m2堆叠加的有点多了 拆开堆叠 降低m1m2赔付比重到 分一部分给到m3m4m5, free 里减少一点m1m2 的赔付 加了一点wild降低波动
N30: respin里提升出刀的概率 平均出刀0.99提升到1.12，降低刀平均切的个数4.08降到3.6，另一半出bonus的概率提升
A32: 机台 | B32: 阶段 | C32: 赢倍 | D32: 占比 | M32: v8： | N32: 调整第四列出scatter的概率 将234列SCATTER都调整成差不多的概率，减小nearmiss的概率，free触发间隔保持不变，
A33: 1112 | B33: base | C33: [100,200) | D33: 1.5e-05 | N33: respin里减小不同bonus另一半出东西不同的差异 (主要是提升第一组出倍数的概率)，提升一点点太刀变乘倍后另一半出bonus的概率
A34: 1112 | B34: base | C34: [50,100) | D34: 0.000156
A35: 1112 | B35: base | C35: [30,50) | D35: 0.000386 | M35: v9: | N35: 提升base下 bonus分裂概率 降低轮带出bonus概率 respin间隔保持109不变
A36: 1112 | B36: base | C36: [20,30) | D36: 0.000724
A37: 1112 | B37: base | C37: [10,20) | D37: 0.002729 | M37: v10: | N37: 提升 刀变乘倍之后以及jackpot 另一半出的概率 ，提升minor mini配比 降低一点太刀切的数量3.375
A38: 1112 | B38: base | C38: [8,10) | D38: 0.001437
A39: 1112 | B39: base | C39: [5,8) | D39: 0.004753
A40: 1112 | B40: base | C40: [4,5) | D40: 0.003087
A41: 1112 | B41: base | C41: [2,4) | D41: 0.020333
A42: 1112 | B42: base | C42: [1,2) | D42: 0.032659
...

Sheet Pay Line
A2: Base | D2: 1 | J2: 2 | P2: 3 | V2: 4 | AB2: 5 | AH2: 6 | AN2: 7 | AT2: 8 | AZ2: 9 | BF2: 10 | BN2: ID
C3: 4 | BN3: 1 | BO3: { | BP3: {=IF(SUM(IF(D3:D6="x",$C$3:$C$6,0))=0,"},{",SUM(IF(D3:D6="x",$C$3:$C$6,0)))} -> 2 | BQ3: {=IF(SUM(IF(E3:E6="x",$C$3:$C$6,0))=0,"},{",SUM(IF(E3:E6="x",$C$3:$C$6,0)))} -> 2 | BR3: {=IF(SUM(IF(F3:F6="x",$C$3:$C$6,0))=0,"},{",SUM(IF(F3:F6="x",$C$3:$C$6,0)))} -> 2 | BS3: {=IF(SUM(IF(G3:G6="x",$C$3:$C$6,0))=0,"},{",SUM(IF(G3:G6="x",$C$3:$C$6,0)))} -> 2 | BT3: {=IF(SUM(IF(H3:H6="x",$C$3:$C$6,0))=0,"},{",SUM(IF(H3:H6="x",$C$3:$C$6,0)))} -> 2 | BU3: {=IF(SUM(IF(I3:I6="x",$C$3:$C$6,0))=0,"},{",SUM(IF(I3:I6="x",$C$3:$C$6,0)))} -> },{ | BV3: {=IF(SUM(IF(J3:J6="x",$C$3:$C$6,0))=0,"},{",SUM(IF(J3:J6="x",$C$3:$C$6,0)))} -> 3 | BW3: {=IF(SUM(IF(K3:K6="x",$C$3:$C$6,0))=0,"},{",SUM(IF(K3:K6="x",$C$3:$C$6,0)))} -> 3 | ... DV3: {=IF(SUM(IF(BJ3:BJ6="x",$C$3:$C$6,0))=0,"},{",SUM(IF(BJ3:BJ6="x",$C$3:$C$6,0)))} -> 1 | DW3: },
C4: 3 | J4: x | K4: x | L4: x | M4: x | N4: x | V4: x | Z4: x | AD4: x | AH4: x | AI4: x | AQ4: x | AR4: x | AU4: x | BC4: x | BF4: x | BN4: 11 | BO4: { | BP4: {=IF(SUM(IF(D9:D12="x",$C$9:$C$12,0))=0,"},{",SUM(IF(D9:D12="x",$C$9:$C$12,0)))} -> 1 | BQ4: {=IF(SUM(IF(E9:E12="x",$C$9:$C$12,0))=0,"},{",SUM(IF(E9:E12="x",$C$9:$C$12,0)))} -> 2 | BR4: {=IF(SUM(IF(F9:F12="x",$C$9:$C$12,0))=0,"},{",SUM(IF(F9:F12="x",$C$9:$C$12,0)))} -> 2 | BS4: {=IF(SUM(IF(G9:G12="x",$C$9:$C$12,0))=0,"},{",SUM(IF(G9:G12="x",$C$9:$C$12,0)))} -> 2 | BT4: {=IF(SUM(IF(H9:H12="x",$C$9:$C$12,0))=0,"},{",SUM(IF(H9:H12="x",$C$9:$C$12,0)))} -> 3 | BU4: {=IF(SUM(IF(I9:I12="x",$C$9:$C$12,0))=0,"},{",SUM(IF(I9:I12="x",$C$9:$C$12,0)))} -> },{ | BV4: {=IF(SUM(IF(J9:J12="x",$C$9:$C$12,0))=0,"},{",SUM(IF(J9:J12="x",$C$9:$C$12,0)))} -> 2 | BW4: {=IF(SUM(IF(K9:K12="x",$C$9:$C$12,0))=0,"},{",SUM(IF(K9:K12="x",$C$9:$C$12,0)))} -> 3 | ... DV4: {=IF(SUM(IF(BJ9:BJ12="x",$C$9:$C$12,0))=0,"},{",SUM(IF(BJ9:BJ12="x",$C$9:$C$12,0)))} -> 1 | DW4: },
C5: 2 | D5: x | E5: x | F5: x | G5: x | H5: x | W5: x | Y5: x | AC5: x | AE5: x | AJ5: x | AP5: x | AT5: x | AV5: x | AX5: x | AZ5: x | BB5: x | BD5: x | BG5: x | BH5: x | BI5: x | BN5: 21 | BO5: { | BP5: =IF((IF(D15="x",4,0)+IF(D16="x",3,0)+IF(D17="x",2,0)+IF(D18="x",1,0))=0,"},{",(IF(D15="x",4,0)+IF(D16="x",3,0)+IF(D17="x",2,0)+IF(D18="x",1,0))) -> 1 | BQ5: =IF((IF(E15="x",4,0)+IF(E16="x",3,0)+IF(E17="x",2,0)+IF(E18="x",1,0))=0,"},{",(IF(E15="x",4,0)+IF(E16="x",3,0)+IF(E17="x",2,0)+IF(E18="x",1,0))) -> 1 | BR5: =IF((IF(F15="x",4,0)+IF(F16="x",3,0)+IF(F17="x",2,0)+IF(F18="x",1,0))=0,"},{",(IF(F15="x",4,0)+IF(F16="x",3,0)+IF(F17="x",2,0)+IF(F18="x",1,0))) -> 1 | BS5: =IF((IF(G15="x",4,0)+IF(G16="x",3,0)+IF(G17="x",2,0)+IF(G18="x",1,0))=0,"},{",(IF(G15="x",4,0)+IF(G16="x",3,0)+IF(G17="x",2,0)+IF(G18="x",1,0))) -> 2 | BT5: =IF((IF(H15="x",4,0)+IF(H16="x",3,0)+IF(H17="x",2,0)+IF(H18="x",1,0))=0,"},{",(IF(H15="x",4,0)+IF(H16="x",3,0)+IF(H17="x",2,0)+IF(H18="x",1,0))) -> 3 | BU5: =IF((IF(I15="x",4,0)+IF(I16="x",3,0)+IF(I17="x",2,0)+IF(I18="x",1,0))=0,"},{",(IF(I15="x",4,0)+IF(I16="x",3,0)+IF(I17="x",2,0)+IF(I18="x",1,0))) -> },{ | BV5: =IF((IF(J15="x",4,0)+IF(J16="x",3,0)+IF(J17="x",2,0)+IF(J18="x",1,0))=0,"},{",(IF(J15="x",4,0)+IF(J16="x",3,0)+IF(J17="x",2,0)+IF(J18="x",1,0))) -> 3 | BW5: =IF((IF(K15="x",4,0)+IF(K16="x",3,0)+IF(K17="x",2,0)+IF(K18="x",1,0))=0,"},{",(IF(K15="x",4,0)+IF(K16="x",3,0)+IF(K17="x",2,0)+IF(K18="x",1,0))) -> 2 | ... DV5: =IF((IF(BJ15="x",4,0)+IF(BJ16="x",3,0)+IF(BJ17="x",2,0)+IF(BJ18="x",1,0))=0,"},{",(IF(BJ15="x",4,0)+IF(BJ16="x",3,0)+IF(BJ17="x",2,0)+IF(BJ18="x",1,0))) -> 1 | DW5: },
C6: 1 | P6: x | Q6: x | R6: x | S6: x | T6: x | X6: x | AB6: x | AF6: x | AK6: x | AL6: x | AN6: x | AO6: x | AW6: x | BA6: x | BJ6: x | BN6: 31 | BO6: { | BP6: =IF((IF(D21="x",4,0)+IF(D22="x",3,0)+IF(D23="x",2,0)+IF(D24="x",1,0))=0,"},{",(IF(D21="x",4,0)+IF(D22="x",3,0)+IF(D23="x",2,0)+IF(D24="x",1,0))) -> },{ | BQ6: =IF((IF(E21="x",4,0)+IF(E22="x",3,0)+IF(E23="x",2,0)+IF(E24="x",1,0))=0,"},{",(IF(E21="x",4,0)+IF(E22="x",3,0)+IF(E23="x",2,0)+IF(E24="x",1,0))) -> },{ | BR6: =IF((IF(F21="x",4,0)+IF(F22="x",3,0)+IF(F23="x",2,0)+IF(F24="x",1,0))=0,"},{",(IF(F21="x",4,0)+IF(F22="x",3,0)+IF(F23="x",2,0)+IF(F24="x",1,0))) -> },{ | BS6: =IF((IF(G21="x",4,0)+IF(G22="x",3,0)+IF(G23="x",2,0)+IF(G24="x",1,0))=0,"},{",(IF(G21="x",4,0)+IF(G22="x",3,0)+IF(G23="x",2,0)+IF(G24="x",1,0))) -> },{ | BT6: =IF((IF(H21="x",4,0)+IF(H22="x",3,0)+IF(H23="x",2,0)+IF(H24="x",1,0))=0,"},{",(IF(H21="x",4,0)+IF(H22="x",3,0)+IF(H23="x",2,0)+IF(H24="x",1,0))) -> },{ | BU6: =IF((IF(I21="x",4,0)+IF(I22="x",3,0)+IF(I23="x",2,0)+IF(I24="x",1,0))=0,"},{",(IF(I21="x",4,0)+IF(I22="x",3,0)+IF(I23="x",2,0)+IF(I24="x",1,0))) -> },{ | BV6: =IF((IF(J21="x",4,0)+IF(J22="x",3,0)+IF(J23="x",2,0)+IF(J24="x",1,0))=0,"},{",(IF(J21="x",4,0)+IF(J22="x",3,0)+IF(J23="x",2,0)+IF(J24="x",1,0))) -> },{ | BW6: =IF((IF(K21="x",4,0)+IF(K22="x",3,0)+IF(K23="x",2,0)+IF(K24="x",1,0))=0,"},{",(IF(K21="x",4,0)+IF(K22="x",3,0)+IF(K23="x",2,0)+IF(K24="x",1,0))) -> },{ | ... DV6: =IF((IF(BJ21="x",4,0)+IF(BJ22="x",3,0)+IF(BJ23="x",2,0)+IF(BJ24="x",1,0))=0,"},{",(IF(BJ21="x",4,0)+IF(BJ22="x",3,0)+IF(BJ23="x",2,0)+IF(BJ24="x",1,0))) -> },{ | DW6: },
BN7: 41 | BO7: { | BP7: {=IF(SUM(IF(D27:D34="x",$C$27:$C$34,0))=0,"},{",SUM(IF(D27:D34="x",$C$27:$C$34,0)))} -> },{ | BQ7: {=IF(SUM(IF(E27:E34="x",$C$27:$C$34,0))=0,"},{",SUM(IF(E27:E34="x",$C$27:$C$34,0)))} -> },{ | BR7: {=IF(SUM(IF(F27:F34="x",$C$27:$C$34,0))=0,"},{",SUM(IF(F27:F34="x",$C$27:$C$34,0)))} -> },{ | BS7: {=IF(SUM(IF(G27:G34="x",$C$27:$C$34,0))=0,"},{",SUM(IF(G27:G34="x",$C$27:$C$34,0)))} -> },{ | BT7: {=IF(SUM(IF(H27:H34="x",$C$27:$C$34,0))=0,"},{",SUM(IF(H27:H34="x",$C$27:$C$34,0)))} -> },{ | BU7: {=IF(SUM(IF(I27:I34="x",$C$27:$C$34,0))=0,"},{",SUM(IF(I27:I34="x",$C$27:$C$34,0)))} -> },{ | BV7: {=IF(SUM(IF(J27:J34="x",$C$27:$C$34,0))=0,"},{",SUM(IF(J27:J34="x",$C$27:$C$34,0)))} -> },{ | BW7: {=IF(SUM(IF(K27:K34="x",$C$27:$C$34,0))=0,"},{",SUM(IF(K27:K34="x",$C$27:$C$34,0)))} -> },{ | ... DV7: {=IF(SUM(IF(BJ27:BJ34="x",$C$27:$C$34,0))=0,"},{",SUM(IF(BJ27:BJ34="x",$C$27:$C$34,0)))} -> },{ | DW7: },
D8: 11 | J8: 12 | P8: 13 | V8: 14 | AB8: 15 | AH8: 16 | AN8: 17 | AT8: 18 | AZ8: 19 | BF8: 20 | BN8: 51 | BO8: { | BP8: {=IF(SUM(IF(D37:D44="x",$C$37:$C$44,0))=0,"},{",SUM(IF(D37:D44="x",$C$37:$C$44,0)))} -> },{ | BQ8: {=IF(SUM(IF(E37:E44="x",$C$37:$C$44,0))=0,"},{",SUM(IF(E37:E44="x",$C$37:$C$44,0)))} -> },{ | BR8: {=IF(SUM(IF(F37:F44="x",$C$37:$C$44,0))=0,"},{",SUM(IF(F37:F44="x",$C$37:$C$44,0)))} -> },{ | BS8: {=IF(SUM(IF(G37:G44="x",$C$37:$C$44,0))=0,"},{",SUM(IF(G37:G44="x",$C$37:$C$44,0)))} -> },{ | BT8: {=IF(SUM(IF(H37:H44="x",$C$37:$C$44,0))=0,"},{",SUM(IF(H37:H44="x",$C$37:$C$44,0)))} -> },{ | BU8: {=IF(SUM(IF(I37:I44="x",$C$37:$C$44,0))=0,"},{",SUM(IF(I37:I44="x",$C$37:$C$44,0)))} -> },{ | BV8: {=IF(SUM(IF(J37:J44="x",$C$37:$C$44,0))=0,"},{",SUM(IF(J37:J44="x",$C$37:$C$44,0)))} -> },{ | BW8: {=IF(SUM(IF(K37:K44="x",$C$37:$C$44,0))=0,"},{",SUM(IF(K37:K44="x",$C$37:$C$44,0)))} -> },{ | ... DV8: {=IF(SUM(IF(BJ37:BJ44="x",$C$37:$C$44,0))=0,"},{",SUM(IF(BJ37:BJ44="x",$C$37:$C$44,0)))} -> },{ | DW8: },
C9: 4 | BN9: 61 | BO9: { | BP9: {=IF(SUM(IF(D47:D54="x",$C$47:$C$54,0))=0,"},{",SUM(IF(D47:D54="x",$C$47:$C$54,0)))} -> },{ | BQ9: {=IF(SUM(IF(E47:E54="x",$C$47:$C$54,0))=0,"},{",SUM(IF(E47:E54="x",$C$47:$C$54,0)))} -> },{ | BR9: {=IF(SUM(IF(F47:F54="x",$C$47:$C$54,0))=0,"},{",SUM(IF(F47:F54="x",$C$47:$C$54,0)))} -> },{ | BS9: {=IF(SUM(IF(G47:G54="x",$C$47:$C$54,0))=0,"},{",SUM(IF(G47:G54="x",$C$47:$C$54,0)))} -> },{ | BT9: {=IF(SUM(IF(H47:H54="x",$C$47:$C$54,0))=0,"},{",SUM(IF(H47:H54="x",$C$47:$C$54,0)))} -> },{ | BU9: {=IF(SUM(IF(I47:I54="x",$C$47:$C$54,0))=0,"},{",SUM(IF(I47:I54="x",$C$47:$C$54,0)))} -> },{ | BV9: {=IF(SUM(IF(J47:J54="x",$C$47:$C$54,0))=0,"},{",SUM(IF(J47:J54="x",$C$47:$C$54,0)))} -> },{ | BW9: {=IF(SUM(IF(K47:K54="x",$C$47:$C$54,0))=0,"},{",SUM(IF(K47:K54="x",$C$47:$C$54,0)))} -> },{ | ... DV9: {=IF(SUM(IF(BJ47:BJ54="x",$C$47:$C$54,0))=0,"},{",SUM(IF(BJ47:BJ54="x",$C$47:$C$54,0)))} -> },{ | DW9: },
C10: 3 | H10: x | K10: x | L10: x | T10: x | X10: x | AF10: x | AH10: x | AI10: x | AQ10: x | AU10: x | BC10: x | BD10: x | BF10: x | BG10: x | BH10: x | BN10: 71 | BO10: { | BP10: {=IF(SUM(IF(D57:D64="x",$C$57:$C$64,0))=0,"},{",SUM(IF(D57:D64="x",$C$57:$C$64,0)))} -> },{ | BQ10: {=IF(SUM(IF(E57:E64="x",$C$57:$C$64,0))=0,"},{",SUM(IF(E57:E64="x",$C$57:$C$64,0)))} -> },{ | BR10: {=IF(SUM(IF(F57:F64="x",$C$57:$C$64,0))=0,"},{",SUM(IF(F57:F64="x",$C$57:$C$64,0)))} -> },{ | BS10: {=IF(SUM(IF(G57:G64="x",$C$57:$C$64,0))=0,"},{",SUM(IF(G57:G64="x",$C$57:$C$64,0)))} -> },{ | BT10: {=IF(SUM(IF(H57:H64="x",$C$57:$C$64,0))=0,"},{",SUM(IF(H57:H64="x",$C$57:$C$64,0)))} -> },{ | BU10: {=IF(SUM(IF(I57:I64="x",$C$57:$C$64,0))=0,"},{",SUM(IF(I57:I64="x",$C$57:$C$64,0)))} -> },{ | BV10: {=IF(SUM(IF(J57:J64="x",$C$57:$C$64,0))=0,"},{",SUM(IF(J57:J64="x",$C$57:$C$64,0)))} -> },{ | BW10: {=IF(SUM(IF(K57:K64="x",$C$57:$C$64,0))=0,"},{",SUM(IF(K57:K64="x",$C$57:$C$64,0)))} -> },{ | ... DV10: {=IF(SUM(IF(BJ57:BJ64="x",$C$57:$C$64,0))=0,"},{",SUM(IF(BJ57:BJ64="x",$C$57:$C$64,0)))} -> },{ | DW10: },
C11: 2 | E11: x | F11: x | G11: x | J11: x | M11: x | P11: x | S11: x | V11: x | W11: x | Y11: x | AB11: x | AC11: x | AE11: x | AJ11: x | AL11: x | AP11: x | AR11: x | AT11: x | AV11: x | AZ11: x | BB11: x | BI11: x | BN11: 81 | BO11: { | BP11: {=IF(SUM(IF(D67:D78="x",$C$67:$C$78,0))=0,"},{",SUM(IF(D67:D78="x",$C$67:$C$78,0)))} -> },{ | BQ11: {=IF(SUM(IF(E67:E78="x",$C$67:$C$78,0))=0,"},{",SUM(IF(E67:E78="x",$C$67:$C$78,0)))} -> },{ | BR11: {=IF(SUM(IF(F67:F78="x",$C$67:$C$78,0))=0,"},{",SUM(IF(F67:F78="x",$C$67:$C$78,0)))} -> },{ | BS11: {=IF(SUM(IF(G67:G78="x",$C$67:$C$78,0))=0,"},{",SUM(IF(G67:G78="x",$C$67:$C$78,0)))} -> },{ | BT11: {=IF(SUM(IF(H67:H78="x",$C$67:$C$78,0))=0,"},{",SUM(IF(H67:H78="x",$C$67:$C$78,0)))} -> },{ | BU11: {=IF(SUM(IF(I67:I78="x",$C$67:$C$78,0))=0,"},{",SUM(IF(I67:I78="x",$C$67:$C$78,0)))} -> },{ | BV11: {=IF(SUM(IF(J67:J78="x",$C$67:$C$78,0))=0,"},{",SUM(IF(J67:J78="x",$C$67:$C$78,0)))} -> },{ | BW11: {=IF(SUM(IF(K67:K78="x",$C$67:$C$78,0))=0,"},{",SUM(IF(K67:K78="x",$C$67:$C$78,0)))} -> },{ | ... DV11: {=IF(SUM(IF(BJ67:BJ78="x",$C$67:$C$78,0))=0,"},{",SUM(IF(BJ67:BJ78="x",$C$67:$C$78,0)))} -> },{ | DW11: },
C12: 1 | D12: x | N12: x | Q12: x | R12: x | Z12: x | AD12: x | AK12: x | AN12: x | AO12: x | AW12: x | AX12: x | BA12: x | BJ12: x | BN12: 91 | BO12: { | BP12: {=IF(SUM(IF(D81:D92="x",$C$81:$C$92,0))=0,"},{",SUM(IF(D81:D92="x",$C$81:$C$92,0)))} -> },{ | BQ12: {=IF(SUM(IF(E81:E92="x",$C$81:$C$92,0))=0,"},{",SUM(IF(E81:E92="x",$C$81:$C$92,0)))} -> },{ | BR12: {=IF(SUM(IF(F81:F92="x",$C$81:$C$92,0))=0,"},{",SUM(IF(F81:F92="x",$C$81:$C$92,0)))} -> },{ | BS12: {=IF(SUM(IF(G81:G92="x",$C$81:$C$92,0))=0,"},{",SUM(IF(G81:G92="x",$C$81:$C$92,0)))} -> },{ | BT12: {=IF(SUM(IF(H81:H92="x",$C$81:$C$92,0))=0,"},{",SUM(IF(H81:H92="x",$C$81:$C$92,0)))} -> },{ | BU12: {=IF(SUM(IF(I81:I92="x",$C$81:$C$92,0))=0,"},{",SUM(IF(I81:I92="x",$C$81:$C$92,0)))} -> },{ | BV12: {=IF(SUM(IF(J81:J92="x",$C$81:$C$92,0))=0,"},{",SUM(IF(J81:J92="x",$C$81:$C$92,0)))} -> },{ | BW12: {=IF(SUM(IF(K81:K92="x",$C$81:$C$92,0))=0,"},{",SUM(IF(K81:K92="x",$C$81:$C$92,0)))} -> },{ | ... DV12: {=IF(SUM(IF(BJ81:BJ92="x",$C$81:$C$92,0))=0,"},{",SUM(IF(BJ81:BJ92="x",$C$81:$C$92,0)))} -> },{ | DW12: },
BN13: 101 | BO13: { | BP13: {=IF(SUM(IF(D95:D106="x",$C$95:$C$106,0))=0,"},{",SUM(IF(D95:D106="x",$C$95:$C$106,0)))} -> },{ | BQ13: {=IF(SUM(IF(E95:E106="x",$C$95:$C$106,0))=0,"},{",SUM(IF(E95:E106="x",$C$95:$C$106,0)))} -> },{ | BR13: {=IF(SUM(IF(F95:F106="x",$C$95:$C$106,0))=0,"},{",SUM(IF(F95:F106="x",$C$95:$C$106,0)))} -> },{ | BS13: {=IF(SUM(IF(G95:G106="x",$C$95:$C$106,0))=0,"},{",SUM(IF(G95:G106="x",$C$95:$C$106,0)))} -> },{ | BT13: {=IF(SUM(IF(H95:H106="x",$C$95:$C$106,0))=0,"},{",SUM(IF(H95:H106="x",$C$95:$C$106,0)))} -> },{ | BU13: {=IF(SUM(IF(I95:I106="x",$C$95:$C$106,0))=0,"},{",SUM(IF(I95:I106="x",$C$95:$C$106,0)))} -> },{ | BV13: {=IF(SUM(IF(J95:J106="x",$C$95:$C$106,0))=0,"},{",SUM(IF(J95:J106="x",$C$95:$C$106,0)))} -> },{ | BW13: {=IF(SUM(IF(K95:K106="x",$C$95:$C$106,0))=0,"},{",SUM(IF(K95:K106="x",$C$95:$C$106,0)))} -> },{ | ... DV13: {=IF(SUM(IF(BJ95:BJ106="x",$C$95:$C$106,0))=0,"},{",SUM(IF(BJ95:BJ106="x",$C$95:$C$106,0)))} -> },{ | DW13: },
D14: 21 | J14: 22 | P14: 23 | V14: 24 | AB14: 25 | AH14: 26 | AN14: 27 | AT14: 28 | AZ14: 29 | BF14: 30 | BN14: 111 | BO14: { | BP14: {=IF(SUM(IF(D109:D120="x",$C$109:$C$120,0))=0,"},{",SUM(IF(D109:D120="x",$C$109:$C$120,0)))} -> },{ | BQ14: {=IF(SUM(IF(E109:E120="x",$C$109:$C$120,0))=0,"},{",SUM(IF(E109:E120="x",$C$109:$C$120,0)))} -> },{ | BR14: {=IF(SUM(IF(F109:F120="x",$C$109:$C$120,0))=0,"},{",SUM(IF(F109:F120="x",$C$109:$C$120,0)))} -> },{ | BS14: {=IF(SUM(IF(G109:G120="x",$C$109:$C$120,0))=0,"},{",SUM(IF(G109:G120="x",$C$109:$C$120,0)))} -> },{ | BT14: {=IF(SUM(IF(H109:H120="x",$C$109:$C$120,0))=0,"},{",SUM(IF(H109:H120="x",$C$109:$C$120,0)))} -> },{ | BU14: {=IF(SUM(IF(I109:I120="x",$C$109:$C$120,0))=0,"},{",SUM(IF(I109:I120="x",$C$109:$C$120,0)))} -> },{ | BV14: {=IF(SUM(IF(J109:J120="x",$C$109:$C$120,0))=0,"},{",SUM(IF(J109:J120="x",$C$109:$C$120,0)))} -> },{ | BW14: {=IF(SUM(IF(K109:K120="x",$C$109:$C$120,0))=0,"},{",SUM(IF(K109:K120="x",$C$109:$C$120,0)))} -> },{ | ... DV14: {=IF(SUM(IF(BJ109:BJ120="x",$C$109:$C$120,0))=0,"},{",SUM(IF(BJ109:BJ120="x",$C$109:$C$120,0)))} -> },{ | DW14: },
C15: 4
C16: 3 | H16: x | J16: x | R16: x | S16: x | T16: x | V16: x | X16: x | Z16: x | AC16: x | AE16: x | AN16: x | AR16: x | AU16: x | AV16: x | AW16: x | BF16: x | BH16: x
C17: 2 | G17: x | K17: x | Q17: x | W17: x | Y17: x | AB17: x | AD17: x | AF17: x | AI17: x | AJ17: x | AK17: x | AO17: x | AP17: x | AQ17: x | AT17: x | AX17: x | AZ17: x | BD17: x | BG17: x | BI17: x
C18: 1 | D18: x | E18: x | F18: x | L18: x | M18: x | N18: x | P18: x | AH18: x | AL18: x | BA18: x | BB18: x | BC18: x | BJ18: x
D20: 31 | J20: 32 | P20: 33 | V20: 34 | AB20: 35 | AH20: 36 | AN20: 37 | AT20: 38 | AZ20: 39 | BF20: 40
C21: 4
C22: 3
C23: 2
C24: 1
D26: 41 | J26: 42 | P26: 43 | V26: 44 | AB26: 45 | AH26: 46 | AN26: 47 | AT26: 48 | AZ26: 49 | BF26: 50
C27: 8
C28: 7
C29: 6
C30: 5
C31: 4
C32: 3
C33: 2
C34: 1
D36: 51 | J36: 52 | P36: 53 | V36: 54 | AB36: 55 | AH36: 56 | AN36: 57 | AT36: 58 | AZ36: 59 | BF36: 60
C37: 8
C38: 7
C39: 6
C40: 5
C41: 4
C42: 3
C43: 2 | DW43: =IF((IF(BL27="x",5,0)+IF(BL28="x",4,0)+IF(BL29="x",3,0)+IF(BL30="x",2,0)+IF(BL31="x",1,0))=0,"",(IF(BL27="x",5,0)+IF(BL28="x",4,0)+IF(BL29="x",3,0)+IF(BL30="x",2,0)+IF(BL31="x",1,0))) | DX43: =IF((IF(BM27="x",5,0)+IF(BM28="x",4,0)+IF(BM29="x",3,0)+IF(BM30="x",2,0)+IF(BM31="x",1,0))=0,"",(IF(BM27="x",5,0)+IF(BM28="x",4,0)+IF(BM29="x",3,0)+IF(BM30="x",2,0)+IF(BM31="x",1,0))) | DY43: =IF((IF(BN27="x",5,0)+IF(BN28="x",4,0)+IF(BN29="x",3,0)+IF(BN30="x",2,0)+IF(BN31="x",1,0))=0,"",(IF(BN27="x",5,0)+IF(BN28="x",4,0)+IF(BN29="x",3,0)+IF(BN30="x",2,0)+IF(BN31="x",1,0))) | DZ43: =IF((IF(BO27="x",5,0)+IF(BO28="x",4,0)+IF(BO29="x",3,0)+IF(BO30="x",2,0)+IF(BO31="x",1,0))=0,"",(IF(BO27="x",5,0)+IF(BO28="x",4,0)+IF(BO29="x",3,0)+IF(BO30="x",2,0)+IF(BO31="x",1,0))) | EA43: =IF((IF(BP27="x",5,0)+IF(BP28="x",4,0)+IF(BP29="x",3,0)+IF(BP30="x",2,0)+IF(BP31="x",1,0))=0,"",(IF(BP27="x",5,0)+IF(BP28="x",4,0)+IF(BP29="x",3,0)+IF(BP30="x",2,0)+IF(BP31="x",1,0))) | EB43: =IF((IF(BQ27="x",5,0)+IF(BQ28="x",4,0)+IF(BQ29="x",3,0)+IF(BQ30="x",2,0)+IF(BQ31="x",1,0))=0,"",(IF(BQ27="x",5,0)+IF(BQ28="x",4,0)+IF(BQ29="x",3,0)+IF(BQ30="x",2,0)+IF(BQ31="x",1,0))) | EC43: =IF((IF(BR27="x",5,0)+IF(BR28="x",4,0)+IF(BR29="x",3,0)+IF(BR30="x",2,0)+IF(BR31="x",1,0))=0,"",(IF(BR27="x",5,0)+IF(BR28="x",4,0)+IF(BR29="x",3,0)+IF(BR30="x",2,0)+IF(BR31="x",1,0))) | ED43: =IF((IF(BS27="x",5,0)+IF(BS28="x",4,0)+IF(BS29="x",3,0)+IF(BS30="x",2,0)+IF(BS31="x",1,0))=0,"",(IF(BS27="x",5,0)+IF(BS28="x",4,0)+IF(BS29="x",3,0)+IF(BS30="x",2,0)+IF(BS31="x",1,0))) | ... EJ43: =IF((IF(BY27="x",5,0)+IF(BY28="x",4,0)+IF(BY29="x",3,0)+IF(BY30="x",2,0)+IF(BY31="x",1,0))=0,"",(IF(BY27="x",5,0)+IF(BY28="x",4,0)+IF(BY29="x",3,0)+IF(BY30="x",2,0)+IF(BY31="x",1,0)))
C44: 1
...

Sheet Pay Table
A2: Bet | B2: =100/G2 -> 2 | C2: For 1 Multiplier | F2: Lines: | G2: 50
M3: Dictionary | N3: ID | O3: Lua ID | P3: DoubleID | R3: Scatter Num | S3: 1 | T3: 2 | U3: 3 | V3: 4 | W3: 5 | X3: 6
B4: Pay Table | M4: M1 | N4: 0 | O4: 1 | P4: =N4+200 -> 200 | R4: BASE | S4: 0 | T4: 0 | U4: 6 | V4: 8 | W4: 10 | X4: 12
B5: Symbol | C5: 2 | D5: 3 | E5: 4 | F5: 5 | G5: 6 | H5: 7 | I5: 8 | J5: 9 | K5: 10 | M5: M2 | N5: 1 | O5: 2 | P5: =N5+200 -> 201 | R5: FREE | S5: 0 | T5: 0 | U5: 0 | V5: 0 | W5: 0 | X5: 0
B6: WILD | C6: 0 | D6: 0 | E6: 0 | F6: 0 | G6: 0 | H6: 0 | I6: 0 | J6: 0 | K6: 0 | M6: M3 | N6: 2 | O6: 3 | P6: =N6+200 -> 202
B7: M1 | C7: 0 | D7: 5 | E7: 15 | F7: 50 | G7: 100 | H7: 200 | I7: 500 | J7: 750 | K7: 1000 | M7: M4 | N7: 3 | O7: 4 | P7: =N7+200 -> 203
B8: M2 | C8: 0 | D8: 5 | E8: 15 | F8: 50 | G8: 100 | H8: 200 | I8: 500 | J8: 750 | K8: 1000 | M8: M5 | N8: 4 | O8: 5 | P8: =N8+200 -> 204
B9: M3 | C9: 0 | D9: 5 | E9: 10 | F9: 25 | G9: 50 | H9: 100 | I9: 200 | J9: 300 | K9: 500 | M9: A | N9: 5 | O9: 6 | P9: =N9 -> 5
B10: M4 | C10: 0 | D10: 5 | E10: 10 | F10: 25 | G10: 50 | H10: 100 | I10: 200 | J10: 300 | K10: 500 | M10: K | N10: 6 | O10: 7 | P10: =N10 -> 6
B11: M5 | C11: 0 | D11: 5 | E11: 10 | F11: 25 | G11: 50 | H11: 100 | I11: 200 | J11: 300 | K11: 500 | M11: Q | N11: 7 | O11: 8 | P11: =N11 -> 7
B12: A | C12: 0 | D12: 2 | E12: 5 | F12: 20 | G12: 30 | H12: 50 | I12: 75 | J12: 100 | K12: 0 | M12: J | N12: 8 | O12: 9 | P12: =N12 -> 8
B13: K | C13: 0 | D13: 2 | E13: 5 | F13: 20 | G13: 30 | H13: 50 | I13: 75 | J13: 100 | K13: 0 | M13: SCATTER | N13: 90 | O13: "s" | P13: 290
B14: Q | C14: 0 | D14: 2 | E14: 5 | F14: 20 | G14: 30 | H14: 50 | I14: 75 | J14: 100 | K14: 0 | M14: LINK | N14: 94 | O14: "v" | P14: =N14+200 -> 294
B15: J | C15: 0 | D15: 2 | E15: 5 | F15: 20 | G15: 30 | H15: 50 | I15: 75 | J15: 100 | K15: 0 | M15: WILD | N15: 92 | O15: "w" | P15: =N15+200 -> 292
B16: SCATTER | C16: 0 | D16: 100 | E16: 200 | F16: 300 | G16: 500 | H16: 0 | I16: 0 | J16: 0 | K16: 0 | M16: SPILT | N16: 95 | P16: 95
B17: LINK | C17: 0 | D17: 0 | E17: 0 | F17: 0 | G17: 0 | H17: 0 | I17: 0 | J17: 0 | K17: 0
D19: 1 | E19: 2 | F19: 3 | G19: 5
C21: =C7/100 -> 0 | D21: =D7/100 -> 0.05 | E21: =E7/100 -> 0.15 | F21: =F7/100 -> 0.5 | G21: =G7/100 -> 1 | H21: =H7/100 -> 2 | I21: =I7/100 -> 5 | J21: =J7/100 -> 7.5 | K21: =K7/100 -> 10
C22: =C8/100 -> 0 | D22: =D8/100 -> 0.05 | E22: =E8/100 -> 0.15 | F22: =F8/100 -> 0.5 | G22: =G8/100 -> 1 | H22: =H8/100 -> 2 | I22: =I8/100 -> 5 | J22: =J8/100 -> 7.5 | K22: =K8/100 -> 10
C23: =C9/100 -> 0 | D23: =D9/100 -> 0.05 | E23: =E9/100 -> 0.1 | F23: =F9/100 -> 0.25 | G23: =G9/100 -> 0.5 | H23: =H9/100 -> 1 | I23: =I9/100 -> 2 | J23: =J9/100 -> 3 | K23: =K9/100 -> 5
C24: =C10/100 -> 0 | D24: =D10/100 -> 0.05 | E24: =E10/100 -> 0.1 | F24: =F10/100 -> 0.25 | G24: =G10/100 -> 0.5 | H24: =H10/100 -> 1 | I24: =I10/100 -> 2 | J24: =J10/100 -> 3 | K24: =K10/100 -> 5
C25: =C11/100 -> 0 | D25: =D11/100 -> 0.05 | E25: =E11/100 -> 0.1 | F25: =F11/100 -> 0.25 | G25: =G11/100 -> 0.5 | H25: =H11/100 -> 1 | I25: =I11/100 -> 2 | J25: =J11/100 -> 3 | K25: =K11/100 -> 5
C26: =C12/100 -> 0 | D26: =D12/100 -> 0.02 | E26: =E12/100 -> 0.05 | F26: =F12/100 -> 0.2 | G26: =G12/100 -> 0.3 | H26: =H12/100 -> 0.5 | I26: =I12/100 -> 0.75 | J26: =J12/100 -> 1 | K26: =K12/100 -> 0
C27: =C13/100 -> 0 | D27: =D13/100 -> 0.02 | E27: =E13/100 -> 0.05 | F27: =F13/100 -> 0.2 | G27: =G13/100 -> 0.3 | H27: =H13/100 -> 0.5 | I27: =I13/100 -> 0.75 | J27: =J13/100 -> 1 | K27: =K13/100 -> 0
J29: 500 | K29: =2500 -> 2500
J30: =J29/5 -> 100 | K30: =K29/J29 -> 5

Sheet Base Game 
A2: Reel Strip
B3: Reel1 | D3: Reel2 | F3: Reel3 | H3: Reel4 | J3: Reel5 | N3: ReelRow | O3: 3 | P3: 3 | Q3: 3 | R3: 3 | S3: 3 | BB3: , | BC3: [ | BD3: ]
B4: =LOOKUP(COUNTA(B$6:B$291)-1,$A$6:$A$291,B$6:B$291) -> M3 | C4: =LOOKUP(COUNTA(C$6:C$291)-1,$A$6:$A$291,C$6:C$291) -> 100 | D4: =LOOKUP(COUNTA(D$6:D$291)-1,$A$6:$A$291,D$6:D$291) -> M3 | E4: =LOOKUP(COUNTA(E$6:E$291)-1,$A$6:$A$291,E$6:E$291) -> 100 | F4: =LOOKUP(COUNTA(F$6:F$291)-1,$A$6:$A$291,F$6:F$291) -> LINK | G4: =LOOKUP(COUNTA(G$6:G$291)-1,$A$6:$A$291,G$6:G$291) -> 50 | H4: =LOOKUP(COUNTA(H$6:H$291)-1,$A$6:$A$291,H$6:H$291) -> K | I4: =LOOKUP(COUNTA(I$6:I$291)-1,$A$6:$A$291,I$6:I$291) -> 100 | ... K4: =LOOKUP(COUNTA(K$6:K$291)-1,$A$6:$A$291,K$6:K$291) -> 100 | BB4: =IFERROR($BC$3&VLOOKUP(B6,'Pay Table'!$M$3:$N$18,2,FALSE)&$BB$3&C6&$BD$3,"") -> [3,100] | BC4: =IFERROR($BC$3&VLOOKUP(D6,'Pay Table'!$M$3:$N$18,2,FALSE)&$BB$3&E6&$BD$3,"") -> [1,100] | BD4: =IFERROR($BC$3&VLOOKUP(F6,'Pay Table'!$M$3:$N$18,2,FALSE)&$BB$3&G6&$BD$3,"") -> [0,100] | BE4: =IFERROR($BC$3&VLOOKUP(H6,'Pay Table'!$M$3:$N$18,2,FALSE)&$BB$3&I6&$BD$3,"") -> [1,100] | BF4: =IFERROR($BC$3&VLOOKUP(J6,'Pay Table'!$M$3:$N$18,2,FALSE)&$BB$3&K6&$BD$3,"") -> [3,100] | BG4: =IFERROR($BC$3&VLOOKUP(G6,'Pay Table'!$M$3:$N$18,2,FALSE)&$BB$3&H6&$BD$3,"") | BI4: =IFERROR($BC$3&VLOOKUP(I6,'Pay Table'!$M$3:$N$18,2,FALSE)&$BB$3&J6&$BD$3,"") | BK4: =IFERROR($BC$3&VLOOKUP(K6,'Pay Table'!$M$3:$N$18,2,FALSE)&$BB$3&L6&$BD$3,"") | BL4: =IFERROR($BC$3&VLOOKUP(L6,'Pay Table'!$M$3:$N$18,2,FALSE)&$BB$3&M6&$BD$3,"")
B5: =LOOKUP(COUNTA(B$6:B$291),$A$6:$A$291,B$6:B$291) -> M4 | C5: =LOOKUP(COUNTA(C$6:C$291),$A$6:$A$291,C$6:C$291) -> 100 | D5: =LOOKUP(COUNTA(D$6:D$291),$A$6:$A$291,D$6:D$291) -> J | E5: =LOOKUP(COUNTA(E$6:E$291),$A$6:$A$291,E$6:E$291) -> 100 | F5: =LOOKUP(COUNTA(F$6:F$291),$A$6:$A$291,F$6:F$291) -> K | G5: =LOOKUP(COUNTA(G$6:G$291),$A$6:$A$291,G$6:G$291) -> 100 | H5: =LOOKUP(COUNTA(H$6:H$291),$A$6:$A$291,H$6:H$291) -> M2 | I5: =LOOKUP(COUNTA(I$6:I$291),$A$6:$A$291,I$6:I$291) -> 100 | ... K5: =LOOKUP(COUNTA(K$6:K$291),$A$6:$A$291,K$6:K$291) -> 100 | O5: 1 | P5: 2 | Q5: 3 | R5: 4 | S5: 5 | V5: 1 | W5: 2 | X5: 3 | Y5: 4 | Z5: 5 | BB5: =IFERROR($BC$3&VLOOKUP(B7,'Pay Table'!$M$3:$N$18,2,FALSE)&$BB$3&C7&$BD$3,"") -> [2,100] | BC5: =IFERROR($BC$3&VLOOKUP(D7,'Pay Table'!$M$3:$N$18,2,FALSE)&$BB$3&E7&$BD$3,"") -> [7,100] | BD5: =IFERROR($BC$3&VLOOKUP(F7,'Pay Table'!$M$3:$N$18,2,FALSE)&$BB$3&G7&$BD$3,"") -> [0,100] | BE5: =IFERROR($BC$3&VLOOKUP(H7,'Pay Table'!$M$3:$N$18,2,FALSE)&$BB$3&I7&$BD$3,"") -> [1,100] | BF5: =IFERROR($BC$3&VLOOKUP(J7,'Pay Table'!$M$3:$N$18,2,FALSE)&$BB$3&K7&$BD$3,"") -> [6,100]
A6: 1 | B6: M4 | C6: 100 | D6: M2 | E6: 100 | F6: M1 | G6: 100 | H6: M2 | I6: 100 | J6: M4 | K6: 100 | N6: ='Pay Table'!B17 -> LINK | O6: {=SUM(IF(B$6:B$289=$N6,1,0)*(C$6:C$289+C$5:C$288+C$4:C$287)/O$3)} -> 315 | P6: {=SUM(IF(D$6:D$289=$N6,1,0)*(E$6:E$289+E$5:E$288+E$4:E$287)/P$3)} -> 315 | Q6: {=SUM(IF(F$6:F$289=$N6,1,0)*(G$6:G$289+G$5:G$288+G$4:G$287)/Q$3)} -> 315 | R6: {=SUM(IF(H$6:H$289=$N6,1,0)*(I$6:I$289+I$5:I$288+I$4:I$287)/R$3)} -> 315 | S6: {=SUM(IF(J$6:J$289=$N6,1,0)*(K$6:K$289+K$5:K$288+K$4:K$287)/S$3)} -> 315 | U6: =N6 -> LINK | W6: =O29/$O$23 -> 0.012160351 | X6: =P29/$O$23 -> 0.0027422629 | Y6: =Q29/$O$23 -> 0.0003886133 | Z6: =R29/$O$23 -> 0.0001170522 | BB6: =IFERROR($BC$3&VLOOKUP(B8,'Pay Table'!$M$3:$N$18,2,FALSE)&$BB$3&C8&$BD$3,"") -> [5,100] | BC6: =IFERROR($BC$3&VLOOKUP(D8,'Pay Table'!$M$3:$N$18,2,FALSE)&$BB$3&E8&$BD$3,"") -> [92,100] | BD6: =IFERROR($BC$3&VLOOKUP(F8,'Pay Table'!$M$3:$N$18,2,FALSE)&$BB$3&G8&$BD$3,"") -> [0,100] | BE6: =IFERROR($BC$3&VLOOKUP(H8,'Pay Table'!$M$3:$N$18,2,FALSE)&$BB$3&I8&$BD$3,"") -> [7,100] | BF6: =IFERROR($BC$3&VLOOKUP(J8,'Pay Table'!$M$3:$N$18,2,FALSE)&$BB$3&K8&$BD$3,"") -> [94,15]
A7: 2 | B7: M3 | C7: 100 | D7: Q | E7: 100 | F7: M1 | G7: 100 | H7: M2 | I7: 100 | J7: K | K7: 100 | N7: ='Pay Table'!B6 -> WILD | O7: {=SUM(IF(B$6:B$289=$N7,1,0)*(C$6:C$289+C$5:C$288+C$4:C$287)/O$3)} -> 0 | P7: {=SUM(IF(D$6:D$289=$N7,1,0)*(E$6:E$289+E$5:E$288+E$4:E$287)/P$3)} -> 333.33333 | Q7: {=SUM(IF(F$6:F$289=$N7,1,0)*(G$6:G$289+G$5:G$288+G$4:G$287)/Q$3)} -> 300 | R7: {=SUM(IF(H$6:H$289=$N7,1,0)*(I$6:I$289+I$5:I$288+I$4:I$287)/R$3)} -> 300 | S7: {=SUM(IF(J$6:J$289=$N7,1,0)*(K$6:K$289+K$5:K$288+K$4:K$287)/S$3)} -> 300 | U7: =N7 -> WILD | W7: =O30/$O$23 -> 0.012427728 | X7: =P30/$O$23 -> 0.0021914555 | Y7: =Q30/$O$23 -> 0.00036118176 | Z7: =R30/$O$23 -> 9.2951189e-05 | BB7: =IFERROR($BC$3&VLOOKUP(B9,'Pay Table'!$M$3:$N$18,2,FALSE)&$BB$3&C9&$BD$3,"") -> [94,15] | BC7: =IFERROR($BC$3&VLOOKUP(D9,'Pay Table'!$M$3:$N$18,2,FALSE)&$BB$3&E9&$BD$3,"") -> [5,140] | BD7: =IFERROR($BC$3&VLOOKUP(F9,'Pay Table'!$M$3:$N$18,2,FALSE)&$BB$3&G9&$BD$3,"") -> [5,140] | BE7: =IFERROR($BC$3&VLOOKUP(H9,'Pay Table'!$M$3:$N$18,2,FALSE)&$BB$3&I9&$BD$3,"") -> [8,100] | BF7: =IFERROR($BC$3&VLOOKUP(J9,'Pay Table'!$M$3:$N$18,2,FALSE)&$BB$3&K9&$BD$3,"") -> [94,25]
A8: 3 | B8: A | C8: 100 | D8: WILD | E8: 100 | F8: M1 | G8: 100 | H8: Q | I8: 100 | J8: LINK | K8: 15 | N8: ='Pay Table'!B7 -> M1 | O8: {=SUM(IF(B$6:B$289=$N8,1,0)*(C$6:C$289+C$5:C$288+C$4:C$287)/O$3)} -> 700 | P8: {=SUM(IF(D$6:D$289=$N8,1,0)*(E$6:E$289+E$5:E$288+E$4:E$287)/P$3)} -> 433.33333 | Q8: {=SUM(IF(F$6:F$289=$N8,1,0)*(G$6:G$289+G$5:G$288+G$4:G$287)/Q$3)} -> 915 | R8: {=SUM(IF(H$6:H$289=$N8,1,0)*(I$6:I$289+I$5:I$288+I$4:I$287)/R$3)} -> 1000 | S8: {=SUM(IF(J$6:J$289=$N8,1,0)*(K$6:K$289+K$5:K$288+K$4:K$287)/S$3)} -> 1283.3333 | U8: =N8 -> M1 | W8: =O31/$O$23 -> 0.02153057 | X8: =P31/$O$23 -> 0.0019753221 | Y8: =Q31/$O$23 -> 0.00015960826 | Z8: =R31/$O$23 -> 2.1140167e-05 | BB8: =IFERROR($BC$3&VLOOKUP(B10,'Pay Table'!$M$3:$N$18,2,FALSE)&$BB$3&C10&$BD$3,"") -> [94,25] | BC8: =IFERROR($BC$3&VLOOKUP(D10,'Pay Table'!$M$3:$N$18,2,FALSE)&$BB$3&E10&$BD$3,"") -> [90,144] | BD8: =IFERROR($BC$3&VLOOKUP(F10,'Pay Table'!$M$3:$N$18,2,FALSE)&$BB$3&G10&$BD$3,"") -> [90,144] | BE8: =IFERROR($BC$3&VLOOKUP(H10,'Pay Table'!$M$3:$N$18,2,FALSE)&$BB$3&I10&$BD$3,"") -> [5,100] | BF8: =IFERROR($BC$3&VLOOKUP(J10,'Pay Table'!$M$3:$N$18,2,FALSE)&$BB$3&K10&$BD$3,"") -> [94,50]
A9: 4 | B9: LINK | C9: 15 | D9: A | E9: 140 | F9: A | G9: 140 | H9: J | I9: 100 | J9: LINK | K9: 25 | N9: ='Pay Table'!B8 -> M2 | O9: {=SUM(IF(B$6:B$289=$N9,1,0)*(C$6:C$289+C$5:C$288+C$4:C$287)/O$3)} -> 500 | P9: {=SUM(IF(D$6:D$289=$N9,1,0)*(E$6:E$289+E$5:E$288+E$4:E$287)/P$3)} -> 716.66667 | Q9: {=SUM(IF(F$6:F$289=$N9,1,0)*(G$6:G$289+G$5:G$288+G$4:G$287)/Q$3)} -> 711.66667 | R9: {=SUM(IF(H$6:H$289=$N9,1,0)*(I$6:I$289+I$5:I$288+I$4:I$287)/R$3)} -> 1133.3333 | S9: {=SUM(IF(J$6:J$289=$N9,1,0)*(K$6:K$289+K$5:K$288+K$4:K$287)/S$3)} -> 1100 | U9: =N9 -> M2 | W9: =O32/$O$23 -> 0.011137091 | X9: =P32/$O$23 -> 0.0015978173 | Y9: =Q32/$O$23 -> 0.00017159402 | Z9: =R32/$O$23 -> 2.5446231e-05 | BB9: =IFERROR($BC$3&VLOOKUP(B11,'Pay Table'!$M$3:$N$18,2,FALSE)&$BB$3&C11&$BD$3,"") -> [94,50] | BC9: =IFERROR($BC$3&VLOOKUP(D11,'Pay Table'!$M$3:$N$18,2,FALSE)&$BB$3&E11&$BD$3,"") -> [6,100] | BD9: =IFERROR($BC$3&VLOOKUP(F11,'Pay Table'!$M$3:$N$18,2,FALSE)&$BB$3&G11&$BD$3,"") -> [8,100] | BE9: =IFERROR($BC$3&VLOOKUP(H11,'Pay Table'!$M$3:$N$18,2,FALSE)&$BB$3&I11&$BD$3,"") -> [3,100] | BF9: =IFERROR($BC$3&VLOOKUP(J11,'Pay Table'!$M$3:$N$18,2,FALSE)&$BB$3&K11&$BD$3,"") -> [7,100]
A10: 5 | B10: LINK | C10: 25 | D10: SCATTER | E10: 144 | F10: SCATTER | G10: 144 | H10: A | I10: 100 | J10: LINK | K10: 50 | N10: ='Pay Table'!B9 -> M3 | O10: {=SUM(IF(B$6:B$289=$N10,1,0)*(C$6:C$289+C$5:C$288+C$4:C$287)/O$3)} -> 900 | P10: {=SUM(IF(D$6:D$289=$N10,1,0)*(E$6:E$289+E$5:E$288+E$4:E$287)/P$3)} -> 583.33333 | Q10: {=SUM(IF(F$6:F$289=$N10,1,0)*(G$6:G$289+G$5:G$288+G$4:G$287)/Q$3)} -> 224.66667 | R10: {=SUM(IF(H$6:H$289=$N10,1,0)*(I$6:I$289+I$5:I$288+I$4:I$287)/R$3)} -> 400 | S10: {=SUM(IF(J$6:J$289=$N10,1,0)*(K$6:K$289+K$5:K$288+K$4:K$287)/S$3)} -> 500 | U10: =N10 -> M3 | W10: =O33/$O$23 -> 0.019470155 | X10: =P33/$O$23 -> 0.0019822628 | Y10: =Q33/$O$23 -> 0.00025130473 | Z10: =R33/$O$23 -> 2.8650376e-05 | BB10: =IFERROR($BC$3&VLOOKUP(B12,'Pay Table'!$M$3:$N$18,2,FALSE)&$BB$3&C12&$BD$3,"") -> [5,100] | BC10: =IFERROR($BC$3&VLOOKUP(D12,'Pay Table'!$M$3:$N$18,2,FALSE)&$BB$3&E12&$BD$3,"") -> [4,100] | BD10: =IFERROR($BC$3&VLOOKUP(F12,'Pay Table'!$M$3:$N$18,2,FALSE)&$BB$3&G12&$BD$3,"") -> [2,100] | BE10: =IFERROR($BC$3&VLOOKUP(H12,'Pay Table'!$M$3:$N$18,2,FALSE)&$BB$3&I12&$BD$3,"") -> [3,100] | BF10: =IFERROR($BC$3&VLOOKUP(J12,'Pay Table'!$M$3:$N$18,2,FALSE)&$BB$3&K12&$BD$3,"") -> [0,100]
A11: 6 | B11: LINK | C11: 50 | D11: K | E11: 100 | F11: J | G11: 100 | H11: M4 | I11: 100 | J11: Q | K11: 100 | N11: ='Pay Table'!B10 -> M4 | O11: {=SUM(IF(B$6:B$289=$N11,1,0)*(C$6:C$289+C$5:C$288+C$4:C$287)/O$3)} -> 783.33333 | P11: {=SUM(IF(D$6:D$289=$N11,1,0)*(E$6:E$289+E$5:E$288+E$4:E$287)/P$3)} -> 241.66667 | Q11: {=SUM(IF(F$6:F$289=$N11,1,0)*(G$6:G$289+G$5:G$288+G$4:G$287)/Q$3)} -> 500 | R11: {=SUM(IF(H$6:H$289=$N11,1,0)*(I$6:I$289+I$5:I$288+I$4:I$287)/R$3)} -> 616.66667 | S11: {=SUM(IF(J$6:J$289=$N11,1,0)*(K$6:K$289+K$5:K$288+K$4:K$287)/S$3)} -> 583.33333 | U11: =N11 -> M4 | W11: =O34/$O$23 -> 0.012079981 | X11: =P34/$O$23 -> 0.0014769363 | Y11: =Q34/$O$23 -> 0.00020573097 | Z11: =R34/$O$23 -> 2.3454671e-05 | BB11: =IFERROR($BC$3&VLOOKUP(B13,'Pay Table'!$M$3:$N$18,2,FALSE)&$BB$3&C13&$BD$3,"") -> [7,100] | BC11: =IFERROR($BC$3&VLOOKUP(D13,'Pay Table'!$M$3:$N$18,2,FALSE)&$BB$3&E13&$BD$3,"") -> [4,100] | BD11: =IFERROR($BC$3&VLOOKUP(F13,'Pay Table'!$M$3:$N$18,2,FALSE)&$BB$3&G13&$BD$3,"") -> [3,100] | BE11: =IFERROR($BC$3&VLOOKUP(H13,'Pay Table'!$M$3:$N$18,2,FALSE)&$BB$3&I13&$BD$3,"") -> [5,100] | BF11: =IFERROR($BC$3&VLOOKUP(J13,'Pay Table'!$M$3:$N$18,2,FALSE)&$BB$3&K13&$BD$3,"") -> [5,100]
A12: 7 | B12: A | C12: 100 | D12: M5 | E12: 100 | F12: M3 | G12: 100 | H12: M4 | I12: 100 | J12: M1 | K12: 100 | N12: ='Pay Table'!B11 -> M5 | O12: {=SUM(IF(B$6:B$289=$N12,1,0)*(C$6:C$289+C$5:C$288+C$4:C$287)/O$3)} -> 700 | P12: {=SUM(IF(D$6:D$289=$N12,1,0)*(E$6:E$289+E$5:E$288+E$4:E$287)/P$3)} -> 748 | Q12: {=SUM(IF(F$6:F$289=$N12,1,0)*(G$6:G$289+G$5:G$288+G$4:G$287)/Q$3)} -> 300 | R12: {=SUM(IF(H$6:H$289=$N12,1,0)*(I$6:I$289+I$5:I$288+I$4:I$287)/R$3)} -> 733.33333 | S12: {=SUM(IF(J$6:J$289=$N12,1,0)*(K$6:K$289+K$5:K$288+K$4:K$287)/S$3)} -> 400 | U12: =N12 -> M5 | W12: =O35/$O$23 -> 0.015730394 | X12: =P35/$O$23 -> 0.0024375756 | Y12: =Q35/$O$23 -> 0.0003428153 | Z12: =R35/$O$23 -> 7.2939425e-05 | BB12: =IFERROR($BC$3&VLOOKUP(B14,'Pay Table'!$M$3:$N$18,2,FALSE)&$BB$3&C14&$BD$3,"") -> [3,100] | BC12: =IFERROR($BC$3&VLOOKUP(D14,'Pay Table'!$M$3:$N$18,2,FALSE)&$BB$3&E14&$BD$3,"") -> [2,100] | BD12: =IFERROR($BC$3&VLOOKUP(F14,'Pay Table'!$M$3:$N$18,2,FALSE)&$BB$3&G14&$BD$3,"") -> [0,100] | BE12: =IFERROR($BC$3&VLOOKUP(H14,'Pay Table'!$M$3:$N$18,2,FALSE)&$BB$3&I14&$BD$3,"") -> [4,100] | BF12: =IFERROR($BC$3&VLOOKUP(J14,'Pay Table'!$M$3:$N$18,2,FALSE)&$BB$3&K14&$BD$3,"") -> [6,100]
